Workbook

Sheet Emp Master
B1: kuldeep | C1: SE | D1: CS | L1: =SUBTOTAL(9,L4:L1516) -> 7786257 | P1: =SUBTOTAL(9,P4:P1516) -> 5725687 | T1: Put-> | U1: US, S | V1: Increament Method | Y1: =SUBTOTAL(9,Y4:Y1516) -> 5846320 | Z1: 35000 | AC1: 0.4 | AD1: 0.3 | AE1: 0.3 | AF1: For Under 30K | AK1: =COLUMN() -> 37
A2: =SUBTOTAL(3,A4:A1516) -> 255 | B2: Max No is | C2: =IFERROR(__xludf.DUMMYFUNCTION("ARRAY_CONSTRAIN(SORT(FILTER(RIGHT($A:$A,4),LEFT($A:$A,2)=C1),1,false),1,1)"),"1467") -> 1467 | D2: =IFERROR(__xludf.DUMMYFUNCTION("ARRAY_CONSTRAIN(SORT(FILTER(RIGHT($A:$A,4),LEFT($A:$A,2)=D1),1,false),1,1)"),"1265") -> 1265 | G2: DUTY TIME | L2: Current | P2: Last Sal | V2: Old | X2: N= No | Y2: 100 | Z2: =CONCAT("Base: ",(Z1*AB2)) -> Base: 17500 | AB2: 0.5 | AC2: 0.2 | AD2: 0.15 | AE2: 0.15 | AF2: For Over 30K | AM2: =today() -> 46292 | AQ2: Asset | AR2: Asset | AS2: Asset | AT2: Asset
A3: Employee Code | B3: NAME | C3: Type | D3: Department | E3: Designation | F3: Location | G3: IN | H3: OUT | I3: Working HRS | J3: DOJ | K3: COMPANY | L3: Salary | M3: Chq/Cs | N3: Status | O3: DoL inc | P3: L Sal | Q3: TDS | R3: Terminated Date | S3: ESI | T3: OT | U3: Skill Level | V3: Salary | W3: Inc % | X3: Extra Col | Y3: Inc 2025 | Z3: Remarks | AA3: New Sal for Basic+HRA | AB3: Basic | AC3: HRA | AD3: Conveyance | AE3: Others | AF3: Total Salary Ok? | AG3: Min Salary ? | AH3: Check in Advance | AI3: Sal Made? | AJ3: PF to calculate (Y/N) | AK3: Room Allowed | AL3: Aged in Year | AM3: Aged in Month | AN3: Shoe Size | AO3: T Shirt Size | AP3: jacket Size | AQ3: ID card | AR3: Tshirt | AS3: Shoe | AT3: Jacket
A4: CO1001 | B4: HARESH | C4: Comm | D4: Sales & Marketing | E4: Sales & Marketing | F4: BENG | G4: 0.375 | H4: 0.75 | I4: =IF(ISBLANK(H4),,H4-G4) -> 0.375 | K4: SE | L4: =Y4 -> 11800 | M4: Chq | N4: Employed | P4: 11800 | Q4: 200 | T4: NO | V4: =P4 -> 11800 | W4: 0 | Y4: =if(W4="",V4,round(V4*(1+W4),-1)) -> 11800 | AA4: =L4 -> 11800 | AB4: =IFS(AA4<=12000,AA4,AND(AA4>12000,AA4<=15200),15200,AND(AA4>15200,AA4<15500),AA4,AND(AA4>=15500,AA4<30000),15500,AA4>=30000,AA4*$AB$2) -> 11800 | AC4: =IF($AA4<=$Z$1,($AA4-$AB4)*AC$1,$AA4*AC$2) -> 0 | AD4: =IF($AA4<=$Z$1,($AA4-$AB4)*AD$1,$AA4*AD$2)+AA4-AB4-AC4-IF($AA4<=$Z$1,($AA4-$AB4)*AD$1,$AA4*AD$2) -> 0 | AE4: 0 | AF4: =IF(SUM(AB4:AE4)=AA4,"OK","NO") -> OK | AG4: =IF(U4="US",IF(AA4<9750,"Under","US OK"),IF(U4="S",IF(AA4<12000,"Under","S OK"),"Skill Missing")) -> Skill Missing | AH4: =VLOOKUP(A4,'Advance Sheet'!$A$4:$A$165,1,FALSE) -> #REF! | AI4: =IF(ISERROR(VLOOKUP(A4,'SNP Sal Main'!$A$3:$A1516,1,false))=FALSE,"SNP SAL",IF(ISERROR(VLOOKUP(A4,'Rest Sal Main org'!$A$3:$A1516,1,false))=FALSE,"Rest Sal","Not Found")) -> Not Found | AJ4: N | AM4: =if(J4="","",datedif(J4,$AM$2,"M"))
A5: CO1002 | B5: V UDAI SHANKAR | C5: Prof | D5: Agent | E5: Mis | F5: MUM | G5: 0.375 | H5: 0.75 | I5: =IF(ISBLANK(H5),,H5-G5) -> 0.375 | K5: SE | L5: =Y5 -> 100000 | M5: Chq | N5: Employed | P5: 100000 | Q5: 10000 | T5: NO | V5: =P5 -> 100000 | W5: 0 | Y5: =if(W5="",V5,round(V5*(1+W5),-1)) -> 100000 | Z5: =CONCATENATE(VLOOKUP(A5,'Copy of Emp Master'!$A$3:$Q$227,COLUMN(#REF!),FALSE)," ",VLOOKUP(A5,'Copy of Emp Master'!$A$3:$Q$227,COLUMN(#REF!),FALSE)) -> #REF! | AA5: =L5 -> 100000 | AB5: =IFS(AA5<=12000,AA5,AND(AA5>12000,AA5<=15200),15200,AND(AA5>15200,AA5<15500),AA5,AND(AA5>=15500,AA5<30000),15500,AA5>=30000,AA5*$AB$2) -> 50000 | AC5: =IF($AA5<=$Z$1,($AA5-$AB5)*AC$1,$AA5*AC$2) -> 20000 | AD5: =round(IF($AA5<=$Z$1,($AA5-$AB5)*AD$1,$AA5*AD$2),-1)+AA5-AB5-AC5-round(IF($AA5<=$Z$1,($AA5-$AB5)*AD$1,$AA5*AD$2),-1) -> 30000 | AE5: 0 | AF5: =IF(SUM(AB5:AE5)=AA5,"OK","NO") -> OK | AG5: =IF(U5="US",IF(AA5<9750,"Under","US OK"),IF(U5="S",IF(AA5<12000,"Under","S OK"),"Skill Missing")) -> Skill Missing | AH5: =VLOOKUP(A5,'Advance Sheet'!$A$4:$A$165,1,FALSE) -> #REF! | AI5: =IF(ISERROR(VLOOKUP(A5,'SNP Sal Main'!$A$3:$A1517,1,false))=FALSE,"SNP SAL",IF(ISERROR(VLOOKUP(A5,'Rest Sal Main org'!$A$3:$A1517,1,false))=FALSE,"Rest Sal","Not Found")) -> Not Found | AJ5: N | AM5: =if(J5="","",datedif(J5,$AM$2,"M"))
A6: CO1003 | B6: VARUN KAUSHAL | C6: Comm | D6: Sales & Marketing | E6: Sales & Marketing | F6: DEL | G6: 0.375 | H6: 0.75 | I6: =IF(ISBLANK(H6),,H6-G6) -> 0.375 | K6: SE | L6: =Y6 -> 20000 | M6: Chq | N6: Employed | P6: 20000 | Q6: 400 | T6: NO | V6: =P6 -> 20000 | W6: 0 | Y6: =if(W6="",V6,round(V6*(1+W6),-1)) -> 20000 | AA6: =L6 -> 20000 | AB6: =IFS(AA6<=12000,AA6,AND(AA6>12000,AA6<=15200),15200,AND(AA6>15200,AA6<15500),AA6,AND(AA6>=15500,AA6<30000),15500,AA6>=30000,AA6*$AB$2) -> 15500 | AC6: =IF($AA6<=$Z$1,($AA6-$AB6)*AC$1,$AA6*AC$2) -> 1800 | AD6: =round(IF($AA6<=$Z$1,($AA6-$AB6)*AD$1,$AA6*AD$2),-1)+AA6-AB6-AC6-round(IF($AA6<=$Z$1,($AA6-$AB6)*AD$1,$AA6*AD$2),-1) -> 2700 | AE6: 0 | AF6: =IF(SUM(AB6:AE6)=AA6,"OK","NO") -> OK | AG6: =IF(U6="US",IF(AA6<9750,"Under","US OK"),IF(U6="S",IF(AA6<12000,"Under","S OK"),"Skill Missing")) -> Skill Missing | AH6: =VLOOKUP(A6,'Advance Sheet'!$A$4:$A$165,1,FALSE) -> #REF! | AI6: =IF(ISERROR(VLOOKUP(A6,'SNP Sal Main'!$A$3:$A1518,1,false))=FALSE,"SNP SAL",IF(ISERROR(VLOOKUP(A6,'Rest Sal Main org'!$A$3:$A1518,1,false))=FALSE,"Rest Sal","Not Found")) -> Not Found | AJ6: N | AM6: =if(J6="","",datedif(J6,$AM$2,"M"))
A7: CS1030 | B7: SUBHASH CHAND | C7: Salary | D7: Backend Ops | E7: Executive | F7: DEL | G7: 0.39583333 | H7: 0.79166667 | I7: =IF(ISBLANK(H7),,H7-G7) -> 0.39583333 | J7: 33604 | K7: SE | L7: =Y7 -> 28580 | M7: CS | N7: Employed | O7: 45901 | P7: 25980 | T7: NO | U7: S | V7: =P7 -> 25980 | W7: 0.1 | Y7: =if(W7="",V7,round(V7*(1+W7),-1)) -> 28580 | AA7: =L7 -> 28580 | AB7: =IFS(AA7<=12000,AA7,AND(AA7>12000,AA7<=15200),15200,AND(AA7>15200,AA7<15500),AA7,AND(AA7>=15500,AA7<30000),15500,AA7>=30000,AA7*$AB$2) -> 15500 | AC7: =IF($AA7<=$Z$1,($AA7-$AB7)*AC$1,$AA7*AC$2) -> 5232 | AD7: =round(IF($AA7<=$Z$1,($AA7-$AB7)*AD$1,$AA7*AD$2),-1)+AA7-AB7-AC7-round(IF($AA7<=$Z$1,($AA7-$AB7)*AD$1,$AA7*AD$2),-1) -> 7848 | AE7: 0 | AF7: =IF(SUM(AB7:AE7)=AA7,"OK","NO") -> OK | AG7: =IF(U7="US",IF(AA7<9750,"Under","US OK"),IF(U7="S",IF(AA7<12000,"Under","S OK"),"Skill Missing")) -> S OK | AH7: =VLOOKUP(A7,'Advance Sheet'!$A$4:$A$165,1,FALSE) -> #REF! | AI7: =IF(ISERROR(VLOOKUP(A7,'SNP Sal Main'!$A$3:$A1519,1,false))=FALSE,"SNP SAL",IF(ISERROR(VLOOKUP(A7,'Rest Sal Main org'!$A$3:$A1519,1,false))=FALSE,"Rest Sal","Not Found")) -> Not Found | AJ7: N | AM7: =if(J7="","",datedif(J7,$AM$2,"M")) -> 416
A8: CS1226 | B8: Ankit | C8: Salary | D8: Machining | E8: Operator NC | F8: SNP | G8: 0.33333333 | H8: 0.75 | I8: =IF(ISBLANK(H8),,H8-G8) -> 0.41666667 | J8: 45940 | K8: SE | L8: 13200 | M8: CS | N8: Employed | P8: 12000 | V8: =P8 -> 12000 | W8: 0 | Y8: =if(W8="",V8,round(V8*(1+W8),-1)) -> 12000 | AA8: =L8 -> 13200 | AB8: =IFS(AND(AA8<=15000),15300,AND(AA8>15000,AA8<15500),AA8,AND(AA8>=15500,AA8<$Z$1),15500,AA8>=$Z$1,AA8*$AB$2) -> 15300 | AC8: =round(IF($AA8<=$Z$1,($AA8-$AB8)*AC$1,$AA8*AC$2),-1) -> -840 | AD8: =round(IF($AA8<=$Z$1,($AA8-$AB8)*AD$1,$AA8*AD$2),-1)+AA8-AB8-AC8-round(IF($AA8<=$Z$1,($AA8-$AB8)*AD$1,$AA8*AD$2),-1) -> -1260 | AE8: 0 | AF8: =IF(SUM(AB8:AE8)=AA8,"OK","NO") -> OK | AG8: =IF(U8="US",IF(AA8<9750,"Under","US OK"),IF(U8="S",IF(AA8<12000,"Under","S OK"),"Skill Missing")) -> Skill Missing | AH8: =VLOOKUP(A8,'Advance Sheet'!$A$4:$A$165,1,FALSE) -> #REF! | AI8: =IF(ISERROR(VLOOKUP(A8,'SNP Sal Main'!$A$3:$A1520,1,false))=FALSE,"SNP SAL",IF(ISERROR(VLOOKUP(A8,'Rest Sal Main org'!$A$3:$A1520,1,false))=FALSE,"Rest Sal","Not Found")) -> Not Found | AL8: =if(J8="","",datedif(J8,$AM$2,"Y")) -> 0 | AM8: =if(J8="","",datedif(J8,$AM$2,"M")) -> 11
A9: CS1248 | B9: Narayan Singh Charan | C9: Salary | E9: Misc | F9: SNP | G9: 0.375 | H9: 0.77083333 | I9: =IF(ISBLANK(H9),,H9-G9) -> 0.39583333 | J9: 46038 | K9: SE | L9: 15000 | M9: CS | N9: Employed | P9: 15000 | T9: NO | V9: =P9 -> 15000 | W9: 0 | Y9: =if(W9="",V9,round(V9*(1+W9),-1)) -> 15000 | AA9: 15000 | AB9: =IFS(AND(AA9<=15000),15300,AND(AA9>15000,AA9<15500),AA9,AND(AA9>=15500,AA9<$Z$1),15500,AA9>=$Z$1,AA9*$AB$2) -> 15300 | AC9: =round(IF($AA9<=$Z$1,($AA9-$AB9)*AC$1,$AA9*AC$2),-1) -> -120 | AD9: =round(IF($AA9<=$Z$1,($AA9-$AB9)*AD$1,$AA9*AD$2),-1)+AA9-AB9-AC9-round(IF($AA9<=$Z$1,($AA9-$AB9)*AD$1,$AA9*AD$2),-1) -> -180 | AE9: 0 | AF9: =IF(SUM(AB9:AE9)=AA9,"OK","NO") -> OK | AK9: YES | AM9: =if(J9="","",datedif(J9,$AM$2,"M")) -> 8
A10: CS1251 | B10: Manoj Kumar | C10: Salary | D10: Logistics | E10: Logistics | F10: SNP | I10: =IF(ISBLANK(H10),,H10-G10) | J10: 46064 | K10: SE | L10: 16000 | M10: CS | N10: Employed | P10: 16000 | V10: 16000 | AA10: 16000 | AB10: =IFS(AND(AA10<=15000),15300,AND(AA10>15000,AA10<15500),AA10,AND(AA10>=15500,AA10<$Z$1),15500,AA10>=$Z$1,AA10*$AB$2) -> 15500 | AC10: =round(IF($AA10<=$Z$1,($AA10-$AB10)*AC$1,$AA10*AC$2),-1) -> 200 | AD10: =round(IF($AA10<=$Z$1,($AA10-$AB10)*AD$1,$AA10*AD$2),-1)+AA10-AB10-AC10-round(IF($AA10<=$Z$1,($AA10-$AB10)*AD$1,$AA10*AD$2),-1) -> 300 | AE10: 0 | AF10: =IF(SUM(AB10:AE10)=AA10,"OK","NO") -> OK | AK10: NO | AM10: =if(J10="","",datedif(J10,$AM$2,"M")) -> 7
A11: CS1257 | B11: Dharamveer | C11: Salary | D11: Logistics | E11: Driver | F11: SNP | I11: =IF(ISBLANK(H11),,H11-G11) | J11: 46075 | K11: SE | L11: 20000 | M11: CS | N11: Employed | S11: NO | T11: NO | AA11: 25000 | AB11: =IFS(AND(AA11<=15000),15300,AND(AA11>15000,AA11<15500),AA11,AND(AA11>=15500,AA11<$Z$1),15500,AA11>=$Z$1,AA11*$AB$2) -> 15500 | AC11: =round(IF($AA11<=$Z$1,($AA11-$AB11)*AC$1,$AA11*AC$2),-1) -> 3800 | AD11: =round(IF($AA11<=$Z$1,($AA11-$AB11)*AD$1,$AA11*AD$2),-1)+AA11-AB11-AC11-round(IF($AA11<=$Z$1,($AA11-$AB11)*AD$1,$AA11*AD$2),-1) -> 5700 | AE11: 0 | AK11: NO | AM11: =if(J11="","",datedif(J11,$AM$2,"M")) -> 7
A12: CS1260 | B12: Ramkawar | C12: Salary | D12: Housekeeping | E12: Sweeper | F12: SNP | G12: 0.33333333 | H12: 0.75 | I12: =IF(ISBLANK(H12),,H12-G12) -> 0.41666667 | J12: 46101 | K12: SE | L12: 11000 | M12: CS | N12: Employed | S12: YES | T12: NO | AA12: 11000 | AB12: =IFS(AND(AA12<=15000),15300,AND(AA12>15000,AA12<15500),AA12,AND(AA12>=15500,AA12<$Z$1),15500,AA12>=$Z$1,AA12*$AB$2) -> 15300 | AC12: =round(IF($AA12<=$Z$1,($AA12-$AB12)*AC$1,$AA12*AC$2),-1) -> -1720 | AD12: =round(IF($AA12<=$Z$1,($AA12-$AB12)*AD$1,$AA12*AD$2),-1)+AA12-AB12-AC12-round(IF($AA12<=$Z$1,($AA12-$AB12)*AD$1,$AA12*AD$2),-1) -> -2580 | AE12: 0 | AF12: =IF(SUM(AB12:AE12)=AA12,"OK","NO") -> OK | AK12: NO | AM12: =if(J12="","",datedif(J12,$AM$2,"M")) -> 6
A13: CS1261 | B13: SURENDER SINGH | C13: Salary | D13: LOGISTICS | E13: DRIVER | F13: SNP | G13: 0.33333333 | H13: 0.75 | I13: =IF(ISBLANK(H13),,H13-G13) -> 0.41666667 | J13: 46148 | K13: SE | L13: 23000 | M13: CS | N13: Employed | AA13: =L13 -> 23000 | AB13: =IFS(AND(AA13<=15000),15300,AND(AA13>15000,AA13<15500),AA13,AND(AA13>=15500,AA13<$Z$1),15500,AA13>=$Z$1,AA13*$AB$2) -> 15500 | AC13: =round(IF($AA13<=$Z$1,($AA13-$AB13)*AC$1,$AA13*AC$2),-1) -> 3000 | AD13: =round(IF($AA13<=$Z$1,($AA13-$AB13)*AD$1,$AA13*AD$2),-1)+AA13-AB13-AC13-round(IF($AA13<=$Z$1,($AA13-$AB13)*AD$1,$AA13*AD$2),-1) -> 4500 | AE13: 0 | AF13: =IF(SUM(AB13:AE13)=AA13,"OK","NO") -> OK | AG13: =IF(U13="US",IF(AA13<9750,"Under","US OK"),IF(U13="S",IF(AA13<12000,"Under","S OK"),"Skill Missing")) -> Skill Missing | AI13: =IF(ISERROR(VLOOKUP(A13,'SNP Sal Main'!$A$3:$A1516,1,false))=FALSE,"SNP SAL",IF(ISERROR(VLOOKUP(A13,'Rest Sal Main org'!$A$3:$A1516,1,false))=FALSE,"Rest Sal","Not Found")) -> Not Found | AM13: =if(J13="","",datedif(J13,$AM$2,"M")) -> 4
A14: CS1262 | B14: RAJ KUMAR | C14: Salary | D14: LOGISTICS | E14: DRIVER | F14: SNP | G14: 0.33333333 | H14: 0.75 | I14: =IF(ISBLANK(H14),,H14-G14) -> 0.41666667 | J14: 46148 | K14: SE | L14: 23000 | M14: CS | N14: Employed | AA14: =L14 -> 23000 | AB14: =IFS(AND(AA14<=15000),15300,AND(AA14>15000,AA14<15500),AA14,AND(AA14>=15500,AA14<$Z$1),15500,AA14>=$Z$1,AA14*$AB$2) -> 15500 | AC14: =round(IF($AA14<=$Z$1,($AA14-$AB14)*AC$1,$AA14*AC$2),-1) -> 3000 | AD14: =round(IF($AA14<=$Z$1,($AA14-$AB14)*AD$1,$AA14*AD$2),-1)+AA14-AB14-AC14-round(IF($AA14<=$Z$1,($AA14-$AB14)*AD$1,$AA14*AD$2),-1) -> 4500 | AE14: 0 | AF14: =IF(SUM(AB14:AE14)=AA14,"OK","NO") -> OK | AG14: =IF(U14="US",IF(AA14<9750,"Under","US OK"),IF(U14="S",IF(AA14<12000,"Under","S OK"),"Skill Missing")) -> Skill Missing | AI14: =IF(ISERROR(VLOOKUP(A14,'SNP Sal Main'!$A$3:$A1517,1,false))=FALSE,"SNP SAL",IF(ISERROR(VLOOKUP(A14,'Rest Sal Main org'!$A$3:$A1517,1,false))=FALSE,"Rest Sal","Not Found")) -> Not Found | AM14: =if(J14="","",datedif(J14,$AM$2,"M")) -> 4
A15: CS1263 | B15: SANDEEP | C15: Salary | D15: LOGISTICS | E15: DRIVER | F15: SNP | G15: 0.33333333 | H15: 0.75 | I15: =IF(ISBLANK(H15),,H15-G15) -> 0.41666667 | J15: 46148 | K15: SE | L15: 23000 | M15: CS | N15: Employed | AA15: =L15 -> 23000 | AB15: =IFS(AND(AA15<=15000),15300,AND(AA15>15000,AA15<15500),AA15,AND(AA15>=15500,AA15<$Z$1),15500,AA15>=$Z$1,AA15*$AB$2) -> 15500 | AC15: =round(IF($AA15<=$Z$1,($AA15-$AB15)*AC$1,$AA15*AC$2),-1) -> 3000 | AD15: =round(IF($AA15<=$Z$1,($AA15-$AB15)*AD$1,$AA15*AD$2),-1)+AA15-AB15-AC15-round(IF($AA15<=$Z$1,($AA15-$AB15)*AD$1,$AA15*AD$2),-1) -> 4500 | AE15: 0 | AF15: =IF(SUM(AB15:AE15)=AA15,"OK","NO") -> OK | AG15: =IF(U15="US",IF(AA15<9750,"Under","US OK"),IF(U15="S",IF(AA15<12000,"Under","S OK"),"Skill Missing")) -> Skill Missing | AI15: =IF(ISERROR(VLOOKUP(A15,'SNP Sal Main'!$A$3:$A1518,1,false))=FALSE,"SNP SAL",IF(ISERROR(VLOOKUP(A15,'Rest Sal Main org'!$A$3:$A1518,1,false))=FALSE,"Rest Sal","Not Found")) -> Not Found | AM15: =if(J15="","",datedif(J15,$AM$2,"M")) -> 4
A16: CS1265 | B16: SANJEEV | C16: Salary | D16: Garden | E16: Mali | F16: SNP | G16: 0.33333333 | H16: 0.75 | I16: =IF(ISBLANK(H16),,H16-G16) -> 0.41666667 | J16: 46265 | K16: SE | L16: 13000 | M16: Chq | N16: Employed | AA16: =L16 -> 13000 | AB16: =IFS(AND(AA16<=15000),15300,AND(AA16>15000,AA16<15500),AA16,AND(AA16>=15500,AA16<$Z$1),15500,AA16>=$Z$1,AA16*$AB$2) -> 15300 | AC16: =round(IF($AA16<=$Z$1,($AA16-$AB16)*AC$1,$AA16*AC$2),-1) -> -920 | AD16: =round(IF($AA16<=$Z$1,($AA16-$AB16)*AD$1,$AA16*AD$2),-1)+AA16-AB16-AC16-round(IF($AA16<=$Z$1,($AA16-$AB16)*AD$1,$AA16*AD$2),-1) -> -1380 | AE16: 0
A17: FM1008 | B17: BALI RAM | C17: Salary | D17: Cutting | E17: Helper | F17: MUM | G17: 0.375 | H17: 0.79166667 | I17: =IF(ISBLANK(H17),,H17-G17) -> 0.41666667 | J17: 45809 | K17: FERMECH | L17: 16737 | M17: Chq | N17: Employed | O17: 45536 | P17: 15940 | T17: NO | U17: US | V17: =P17 -> 15940 | W17: 0 | Y17: =if(W17="",V17,round(V17*(1+W17),-1)) -> 15940 | AA17: 16737 | AB17: =IFS(AA17<=12000,AA17,AND(AA17>12000,AA17<=15200),15200,AND(AA17>15200,AA17<15500),AA17,AND(AA17>=15500,AA17<30000),15500,AA17>=30000,AA17*$AB$2) -> 15500 | AC17: =IF($AA17<=$Z$1,($AA17-$AB17)*AC$1,$AA17*AC$2) -> 494.8 | AD17: =round(IF($AA17<=$Z$1,($AA17-$AB17)*AD$1,$AA17*AD$2),-1)+AA17-AB17-AC17-round(IF($AA17<=$Z$1,($AA17-$AB17)*AD$1,$AA17*AD$2),-1) -> 742.2 | AE17: 0 | AF17: =IF(SUM(AB17:AE17)=AA17,"OK","NO") -> OK | AG17: =IF(U17="US",IF(AA17<9750,"Under","US OK"),IF(U17="S",IF(AA17<12000,"Under","S OK"),"Skill Missing")) -> US OK | AH17: =VLOOKUP(A17,'Advance Sheet'!$A$4:$A$165,1,FALSE) -> #REF! | AI17: =IF(ISERROR(VLOOKUP(A17,'SNP Sal Main'!$A$3:$A1516,1,false))=FALSE,"SNP SAL",IF(ISERROR(VLOOKUP(A17,'Rest Sal Main org'!$A$3:$A1516,1,false))=FALSE,"Rest Sal","Not Found")) -> Not Found | AJ17: N | AM17: =if(J17="","",datedif(J17,$AM$2,"M")) -> 15
A18: FM1012 | B18: ABDUR RAJJAK FARUK MONDAL | C18: Salary | D18: Cutting | E18: Operator | F18: MUM | G18: 0.33333333 | H18: 0.75 | I18: =IF(ISBLANK(H18),,H18-G18) -> 0.41666667 | J18: 45809 | K18: FERMECH | L18: 15400 | M18: Chq | N18: Employed | O18: 45809 | P18: 14000 | T18: NO | V18: =P18 -> 14000 | W18: 0 | Y18: =if(W18="",V18,round(V18*(1+W18),-1)) -> 14000 | AA18: =L18 -> 15400 | AB18: =IFS(AND(AA18<=15000),15300,AND(AA18>15000,AA18<15500),AA18,AND(AA18>=15500,AA18<$Z$1),15500,AA18>=$Z$1,AA18*$AB$2) -> 15400 | AC18: =round(IF($AA18<=$Z$1,($AA18-$AB18)*AC$1,$AA18*AC$2),-1) -> 0 | AD18: =round(IF($AA18<=$Z$1,($AA18-$AB18)*AD$1,$AA18*AD$2),-1)+AA18-AB18-AC18-round(IF($AA18<=$Z$1,($AA18-$AB18)*AD$1,$AA18*AD$2),-1) -> 0 | AE18: 0 | AF18: =IF(SUM(AB18:AE18)=AA18,"OK","NO") -> OK | AG18: =IF(U18="US",IF(AA18<9750,"Under","US OK"),IF(U18="S",IF(AA18<12000,"Under","S OK"),"Skill Missing")) -> Skill Missing | AH18: =VLOOKUP(A18,'Advance Sheet'!$A$4:$A$165,1,FALSE) -> #REF! | AI18: =IF(ISERROR(VLOOKUP(A18,'SNP Sal Main'!$A$3:$A1517,1,false))=FALSE,"SNP SAL",IF(ISERROR(VLOOKUP(A18,'Rest Sal Main org'!$A$3:$A1517,1,false))=FALSE,"Rest Sal","Not Found")) -> Not Found | AM18: =if(J18="","",datedif(J18,$AM$2,"M")) -> 15
A19: ITI1009 | B19: VIVEK | C19: Salary | D19: Machining | E19: ITI | F19: SNP | G19: 0.33333333 | H19: 0.75 | I19: =IF(ISBLANK(H19),,H19-G19) -> 0.41666667 | J19: 45614 | K19: SE | L19: =Y19 -> 6550 | M19: CS | N19: Employed | P19: 6550 | T19: YES | V19: =P19 -> 6550 | W19: 0 | Y19: =if(W19="",V19,round(V19*(1+W19),-1)) -> 6550 | AA19: =L19 -> 6550 | AB19: =IFS(AND(AA19<=15000),15300,AND(AA19>15000,AA19<15500),AA19,AND(AA19>=15500,AA19<$Z$1),15500,AA19>=$Z$1,AA19*$AB$2) -> 15300 | AC19: =round(IF($AA19<=$Z$1,($AA19-$AB19)*AC$1,$AA19*AC$2),-1) -> -3500 | AD19: =round(IF($AA19<=$Z$1,($AA19-$AB19)*AD$1,$AA19*AD$2),-1)+AA19-AB19-AC19-round(IF($AA19<=$Z$1,($AA19-$AB19)*AD$1,$AA19*AD$2),-1) -> -5250 | AE19: =IF($AA19<=$Z$1,($AA19-$AB19)*AE$1,$AA19*AE$2) -> -2625 | AF19: =IF(SUM(AB19:AE19)=AA19,"OK","NO") -> NO | AG19: =IF(U19="US",IF(AA19<9750,"Under","US OK"),IF(U19="S",IF(AA19<12000,"Under","S OK"),"Skill Missing")) -> Skill Missing | AH19: =VLOOKUP(A19,'Advance Sheet'!$A$4:$A$165,1,FALSE) -> #REF! | AI19: =IF(ISERROR(VLOOKUP(A19,'SNP Sal Main'!$A$3:$A1518,1,false))=FALSE,"SNP SAL",IF(ISERROR(VLOOKUP(A19,'Rest Sal Main org'!$A$3:$A1518,1,false))=FALSE,"Rest Sal","Not Found")) -> Not Found | AL19: =if(J19="","",datedif(J19,$AM$2,"Y")) -> 1 | AM19: =if(J19="","",datedif(J19,$AM$2,"M")) -> 22
A20: ITI1010 | B20: Dikshit | C20: Salary | D20: Machining | E20: ITI | F20: SNP | G20: 0.33333333 | H20: 0.75 | I20: =IF(ISBLANK(H20),,H20-G20) -> 0.41666667 | J20: 45908 | K20: SE | L20: 12500 | M20: CS | N20: Employed | P20: 12000 | T20: YES | V20: =P20 -> 12000 | W20: 0 | Y20: =if(W20="",V20,round(V20*(1+W20),-1)) -> 12000 | AA20: 12000 | AB20: =IFS(AND(AA20<=15000),15300,AND(AA20>15000,AA20<15500),AA20,AND(AA20>=15500,AA20<$Z$1),15500,AA20>=$Z$1,AA20*$AB$2) -> 15300 | AC20: =round(IF($AA20<=$Z$1,($AA20-$AB20)*AC$1,$AA20*AC$2),-1) -> -1320 | AD20: =round(IF($AA20<=$Z$1,($AA20-$AB20)*AD$1,$AA20*AD$2),-1)+AA20-AB20-AC20-round(IF($AA20<=$Z$1,($AA20-$AB20)*AD$1,$AA20*AD$2),-1) -> -1980 | AE20: 0 | AF20: =IF(SUM(AB20:AE20)=AA20,"OK","NO") -> OK | AG20: =IF(U20="US",IF(AA20<9750,"Under","US OK"),IF(U20="S",IF(AA20<12000,"Under","S OK"),"Skill Missing")) -> Skill Missing | AH20: =VLOOKUP(A20,'Advance Sheet'!$A$4:$A$165,1,FALSE) -> #REF! | AI20: =IF(ISERROR(VLOOKUP(A20,'SNP Sal Main'!$A$3:$A1519,1,false))=FALSE,"SNP SAL",IF(ISERROR(VLOOKUP(A20,'Rest Sal Main org'!$A$3:$A1519,1,false))=FALSE,"Rest Sal","Not Found")) -> Not Found | AL20: =if(J20="","",datedif(J20,$AM$2,"Y")) -> 1 | AM20: =if(J20="","",datedif(J20,$AM$2,"M")) -> 12
A21: ITI1011 | B21: Mohit | C21: Salary | D21: Machining | E21: ITI | F21: SNP | G21: 0.33333333 | H21: 0.75 | I21: =IF(ISBLANK(H21),,H21-G21) -> 0.41666667 | J21: 45908 | K21: SE | L21: 12500 | M21: CS | N21: Employed | P21: 12000 | T21: YES | V21: =P21 -> 12000 | W21: 0 | Y21: =if(W21="",V21,round(V21*(1+W21),-1)) -> 12000 | AA21: 12000 | AB21: =IFS(AND(AA21<=15000),15300,AND(AA21>15000,AA21<15500),AA21,AND(AA21>=15500,AA21<$Z$1),15500,AA21>=$Z$1,AA21*$AB$2) -> 15300 | AC21: =round(IF($AA21<=$Z$1,($AA21-$AB21)*AC$1,$AA21*AC$2),-1) -> -1320 | AD21: =round(IF($AA21<=$Z$1,($AA21-$AB21)*AD$1,$AA21*AD$2),-1)+AA21-AB21-AC21-round(IF($AA21<=$Z$1,($AA21-$AB21)*AD$1,$AA21*AD$2),-1) -> -1980 | AE21: 0 | AF21: =IF(SUM(AB21:AE21)=AA21,"OK","NO") -> OK | AG21: =IF(U21="US",IF(AA21<9750,"Under","US OK"),IF(U21="S",IF(AA21<12000,"Under","S OK"),"Skill Missing")) -> Skill Missing | AH21: =VLOOKUP(A21,'Advance Sheet'!$A$4:$A$165,1,FALSE) -> #REF! | AI21: =IF(ISERROR(VLOOKUP(A21,'SNP Sal Main'!$A$3:$A1520,1,false))=FALSE,"SNP SAL",IF(ISERROR(VLOOKUP(A21,'Rest Sal Main org'!$A$3:$A1520,1,false))=FALSE,"Rest Sal","Not Found")) -> Not Found | AL21: =if(J21="","",datedif(J21,$AM$2,"Y")) -> 1 | AM21: =if(J21="","",datedif(J21,$AM$2,"M")) -> 12
A22: ITI1012 | B22: Nitesh | C22: Salary | D22: Machining | E22: ITI | F22: SNP | G22: 0.33333333 | H22: 0.75 | I22: =IF(ISBLANK(H22),,H22-G22) -> 0.41666667 | J22: 45908 | K22: SE | L22: 14000 | M22: CS | N22: Employed | P22: 12000 | T22: YES | V22: =P22 -> 12000 | W22: 0 | Y22: =if(W22="",V22,round(V22*(1+W22),-1)) -> 12000 | AA22: 14000 | AB22: =IFS(AND(AA22<=15000),15300,AND(AA22>15000,AA22<15500),AA22,AND(AA22>=15500,AA22<$Z$1),15500,AA22>=$Z$1,AA22*$AB$2) -> 15300 | AC22: =round(IF($AA22<=$Z$1,($AA22-$AB22)*AC$1,$AA22*AC$2),-1) -> -520 | AD22: =round(IF($AA22<=$Z$1,($AA22-$AB22)*AD$1,$AA22*AD$2),-1)+AA22-AB22-AC22-round(IF($AA22<=$Z$1,($AA22-$AB22)*AD$1,$AA22*AD$2),-1) -> -780 | AE22: 0 | AF22: =IF(SUM(AB22:AE22)=AA22,"OK","NO") -> OK | AG22: =IF(U22="US",IF(AA22<9750,"Under","US OK"),IF(U22="S",IF(AA22<12000,"Under","S OK"),"Skill Missing")) -> Skill Missing | AH22: =VLOOKUP(A22,'Advance Sheet'!$A$4:$A$165,1,FALSE) -> #REF! | AI22: =IF(ISERROR(VLOOKUP(A22,'SNP Sal Main'!$A$3:$A1521,1,false))=FALSE,"SNP SAL",IF(ISERROR(VLOOKUP(A22,'Rest Sal Main org'!$A$3:$A1521,1,false))=FALSE,"Rest Sal","Not Found")) -> Not Found | AL22: =if(J22="","",datedif(J22,$AM$2,"Y")) -> 1 | AM22: =if(J22="","",datedif(J22,$AM$2,"M")) -> 12
A23: ITI1013 | B23: Saurabh | C23: Salary | D23: Machining | E23: ITI | F23: SNP | G23: 0.33333333 | H23: 0.75 | I23: =IF(ISBLANK(H23),,H23-G23) -> 0.41666667 | J23: 45940 | K23: SE | L23: 12500 | M23: CS | N23: Employed | P23: 12000 | T23: YES | V23: =P23 -> 12000 | W23: 0 | Y23: =if(W23="",V23,round(V23*(1+W23),-1)) -> 12000 | AA23: 12000 | AB23: =IFS(AND(AA23<=15000),15300,AND(AA23>15000,AA23<15500),AA23,AND(AA23>=15500,AA23<$Z$1),15500,AA23>=$Z$1,AA23*$AB$2) -> 15300 | AC23: =round(IF($AA23<=$Z$1,($AA23-$AB23)*AC$1,$AA23*AC$2),-1) -> -1320 | AD23: =round(IF($AA23<=$Z$1,($AA23-$AB23)*AD$1,$AA23*AD$2),-1)+AA23-AB23-AC23-round(IF($AA23<=$Z$1,($AA23-$AB23)*AD$1,$AA23*AD$2),-1) -> -1980 | AE23: 0 | AF23: =IF(SUM(AB23:AE23)=AA23,"OK","NO") -> OK | AG23: =IF(U23="US",IF(AA23<9750,"Under","US OK"),IF(U23="S",IF(AA23<12000,"Under","S OK"),"Skill Missing")) -> Skill Missing | AH23: =VLOOKUP(A23,'Advance Sheet'!$A$4:$A$165,1,FALSE) -> #REF! | AI23: =IF(ISERROR(VLOOKUP(A23,'SNP Sal Main'!$A$3:$A1522,1,false))=FALSE,"SNP SAL",IF(ISERROR(VLOOKUP(A23,'Rest Sal Main org'!$A$3:$A1522,1,false))=FALSE,"Rest Sal","Not Found")) -> Not Found | AL23: =if(J23="","",datedif(J23,$AM$2,"Y")) -> 0 | AM23: =if(J23="","",datedif(J23,$AM$2,"M")) -> 11
A24: ITI1014 | B24: Sorabh | C24: Salary | D24: Machining | E24: ITI | F24: SNP | G24: 0.33333333 | H24: 0.75 | I24: =IF(ISBLANK(H24),,H24-G24) -> 0.41666667 | J24: 45940 | K24: SE | L24: 12500 | M24: CS | N24: Employed | P24: 12000 | T24: YES | V24: =P24 -> 12000 | W24: 0 | Y24: =if(W24="",V24,round(V24*(1+W24),-1)) -> 12000 | AA24: 12000 | AB24: =IFS(AND(AA24<=15000),15300,AND(AA24>15000,AA24<15500),AA24,AND(AA24>=15500,AA24<$Z$1),15500,AA24>=$Z$1,AA24*$AB$2) -> 15300 | AC24: =round(IF($AA24<=$Z$1,($AA24-$AB24)*AC$1,$AA24*AC$2),-1) -> -1320 | AD24: =round(IF($AA24<=$Z$1,($AA24-$AB24)*AD$1,$AA24*AD$2),-1)+AA24-AB24-AC24-round(IF($AA24<=$Z$1,($AA24-$AB24)*AD$1,$AA24*AD$2),-1) -> -1980 | AE24: 0 | AF24: =IF(SUM(AB24:AE24)=AA24,"OK","NO") -> OK | AG24: =IF(U24="US",IF(AA24<9750,"Under","US OK"),IF(U24="S",IF(AA24<12000,"Under","S OK"),"Skill Missing")) -> Skill Missing | AH24: =VLOOKUP(A24,'Advance Sheet'!$A$4:$A$165,1,FALSE) -> #REF! | AI24: =IF(ISERROR(VLOOKUP(A24,'SNP Sal Main'!$A$3:$A1523,1,false))=FALSE,"SNP SAL",IF(ISERROR(VLOOKUP(A24,'Rest Sal Main org'!$A$3:$A1523,1,false))=FALSE,"Rest Sal","Not Found")) -> Not Found | AL24: =if(J24="","",datedif(J24,$AM$2,"Y")) -> 0 | AM24: =if(J24="","",datedif(J24,$AM$2,"M")) -> 11
A25: ITI1015 | B25: Ritesh | C25: Salary | D25: Machining | E25: ITI | F25: SNP | G25: 0.33333333 | H25: 0.75 | I25: =IF(ISBLANK(H25),,H25-G25) -> 0.41666667 | J25: 45985 | K25: SE | L25: =Y25 -> 14000 | M25: CS | N25: Employed | P25: 14000 | T25: YES | V25: =P25 -> 14000 | Y25: =if(W25="",V25,round(V25*(1+W25),-1)) -> 14000 | AA25: 14000 | AB25: =IFS(AND(AA25<=15000),15300,AND(AA25>15000,AA25<15500),AA25,AND(AA25>=15500,AA25<$Z$1),15500,AA25>=$Z$1,AA25*$AB$2) -> 15300 | AC25: =round(IF($AA25<=$Z$1,($AA25-$AB25)*AC$1,$AA25*AC$2),-1) -> -520 | AD25: =round(IF($AA25<=$Z$1,($AA25-$AB25)*AD$1,$AA25*AD$2),-1)+AA25-AB25-AC25-round(IF($AA25<=$Z$1,($AA25-$AB25)*AD$1,$AA25*AD$2),-1) -> -780 | AE25: 0 | AF25: =IF(SUM(AB25:AE25)=AA25,"OK","NO") -> OK | AG25: =IF(U25="US",IF(AA25<9750,"Under","US OK"),IF(U25="S",IF(AA25<12000,"Under","S OK"),"Skill Missing")) -> Skill Missing | AH25: =VLOOKUP(A25,'Advance Sheet'!$A$4:$A$165,1,FALSE) -> #REF! | AI25: =IF(ISERROR(VLOOKUP(A25,'SNP Sal Main'!$A$3:$A1524,1,false))=FALSE,"SNP SAL",IF(ISERROR(VLOOKUP(A25,'Rest Sal Main org'!$A$3:$A1524,1,false))=FALSE,"Rest Sal","Not Found")) -> Not Found | AL25: =if(J25="","",datedif(J25,$AM$2,"Y")) -> 0 | AM25: =if(J25="","",datedif(J25,$AM$2,"M")) -> 10
A26: ITI1016 | B26: Monu | C26: Salary | D26: Machining | E26: ITI | F26: SNP | G26: 0.33333333 | H26: 0.75 | I26: =IF(ISBLANK(H26),,H26-G26) -> 0.41666667 | J26: 45979 | K26: SE | L26: =Y26 -> 14000 | M26: CS | N26: Employed | P26: 14000 | T26: YES | V26: =P26 -> 14000 | Y26: =if(W26="",V26,round(V26*(1+W26),-1)) -> 14000 | AA26: 14000 | AB26: =IFS(AND(AA26<=15000),15300,AND(AA26>15000,AA26<15500),AA26,AND(AA26>=15500,AA26<$Z$1),15500,AA26>=$Z$1,AA26*$AB$2) -> 15300 | AC26: =round(IF($AA26<=$Z$1,($AA26-$AB26)*AC$1,$AA26*AC$2),-1) -> -520 | AD26: =round(IF($AA26<=$Z$1,($AA26-$AB26)*AD$1,$AA26*AD$2),-1)+AA26-AB26-AC26-round(IF($AA26<=$Z$1,($AA26-$AB26)*AD$1,$AA26*AD$2),-1) -> -780 | AE26: 0 | AF26: =IF(SUM(AB26:AE26)=AA26,"OK","NO") -> OK | AG26: =IF(U26="US",IF(AA26<9750,"Under","US OK"),IF(U26="S",IF(AA26<12000,"Under","S OK"),"Skill Missing")) -> Skill Missing | AH26: =VLOOKUP(A26,'Advance Sheet'!$A$4:$A$165,1,FALSE) -> #REF! | AI26: =IF(ISERROR(VLOOKUP(A26,'SNP Sal Main'!$A$3:$A1525,1,false))=FALSE,"SNP SAL",IF(ISERROR(VLOOKUP(A26,'Rest Sal Main org'!$A$3:$A1525,1,false))=FALSE,"Rest Sal","Not Found")) -> Not Found | AL26: =if(J26="","",datedif(J26,$AM$2,"Y")) -> 0 | AM26: =if(J26="","",datedif(J26,$AM$2,"M")) -> 10
A27: MP1001 | B27: JASWANT SINGH MALI | C27: Salary | D27: Garden | E27: Mali | F27: SNP | G27: 0.33333333 | H27: 0.75 | I27: =IF(ISBLANK(H27),,H27-G27) -> 0.41666667 | J27: 43269 | K27: MULTIPACK | L27: =Y27 -> 17140 | M27: Chq | N27: Employed | O27: 45901 | P27: 15440 | T27: NO | U27: US | V27: =P27 -> 15440 | W27: 0.11 | Y27: =if(W27="",V27,round(V27*(1+W27),-1)) -> 17140 | AA27: =L27 -> 17140 | AB27: =IFS(AA27<=12000,AA27,AND(AA27>12000,AA27<=15200),15200,AND(AA27>15200,AA27<15500),AA27,AND(AA27>=15500,AA27<30000),15500,AA27>=30000,AA27*$AB$2) -> 15500 | AC27: =IF($AA27<=$Z$1,($AA27-$AB27)*AC$1,$AA27*AC$2) -> 656 | AD27: =round(IF($AA27<=$Z$1,($AA27-$AB27)*AD$1,$AA27*AD$2),-1)+AA27-AB27-AC27-round(IF($AA27<=$Z$1,($AA27-$AB27)*AD$1,$AA27*AD$2),-1) -> 984 | AE27: 0 | AF27: =IF(SUM(AB27:AE27)=AA27,"OK","NO") -> OK | AG27: =IF(U27="US",IF(AA27<9750,"Under","US OK"),IF(U27="S",IF(AA27<12000,"Under","S OK"),"Skill Missing")) -> US OK | AH27: =VLOOKUP(A27,'Advance Sheet'!$A$4:$A$165,1,FALSE) -> #REF! | AI27: =IF(ISERROR(VLOOKUP(A27,'SNP Sal Main'!$A$3:$A1526,1,false))=FALSE,"SNP SAL",IF(ISERROR(VLOOKUP(A27,'Rest Sal Main org'!$A$3:$A1526,1,false))=FALSE,"Rest Sal","Not Found")) -> Not Found | AJ27: N | AK27: Y | AM27: =if(J27="","",datedif(J27,$AM$2,"M")) -> 99
A28: SA1001 | B28: RAJESH PURI | C28: Prof | D28: Accounts & Finance | E28: Executive Accounts | F28: DEL | G28: 0.375 | H28: 0.77083333 | I28: =IF(ISBLANK(H28),,H28-G28) -> 0.39583333 | J28: 36678 | K28: SE | L28: =Y28 -> 75620 | M28: Chq | N28: Employed | O28: 45901 | P28: 70020 | Q28: 756 | T28: NO | V28: =P28 -> 70020 | W28: 0.08 | Y28: =if(W28="",V28,round(V28*(1+W28),-1)) -> 75620 | AA28: =L28 -> 75620 | AB28: =IFS(AA28<=12000,AA28,AND(AA28>12000,AA28<=15200),15200,AND(AA28>15200,AA28<15500),AA28,AND(AA28>=15500,AA28<30000),15500,AA28>=30000,AA28*$AB$2) -> 37810 | AC28: =IF($AA28<=$Z$1,($AA28-$AB28)*AC$1,$AA28*AC$2) -> 15124 | AD28: =round(IF($AA28<=$Z$1,($AA28-$AB28)*AD$1,$AA28*AD$2),-1)+AA28-AB28-AC28-round(IF($AA28<=$Z$1,($AA28-$AB28)*AD$1,$AA28*AD$2),-1) -> 22686 | AE28: 0 | AF28: =IF(SUM(AB28:AE28)=AA28,"OK","NO") -> OK | AG28: =IF(U28="US",IF(AA28<9750,"Under","US OK"),IF(U28="S",IF(AA28<12000,"Under","S OK"),"Skill Missing")) -> Skill Missing | AH28: =VLOOKUP(A28,'Advance Sheet'!$A$4:$A$165,1,FALSE) -> #REF! | AI28: =IF(ISERROR(VLOOKUP(A28,'SNP Sal Main'!$A$3:$A1527,1,false))=FALSE,"SNP SAL",IF(ISERROR(VLOOKUP(A28,'Rest Sal Main org'!$A$3:$A1527,1,false))=FALSE,"Rest Sal","Not Found")) -> Not Found | AJ28: N | AM28: =if(J28="","",datedif(J28,$AM$2,"M")) -> 315
A29: SE1001 | B29: NAVEEN CHANDRA | C29: Salary | D29: Cutting | E29: Supervisior | F29: SNP | G29: 0.33333333 | H29: 0.75 | I29: =IF(ISBLANK(H29),,H29-G29) -> 0.41666667 | J29: 41974 | K29: SE | L29: 37383 | M29: Chq | N29: Employed | O29: 45901 | P29: 36650 | T29: YES | U29: S | V29: =P29 -> 36650 | W29: 0.1 | Y29: =if(W29="",V29,round(V29*(1+W29),-1)) -> 40320 | AA29: =L29 -> 37383 | AB29: =roundup(IFS(AND(AA29<=15000),15300,AND(AA29>15000,AA29<15500),AA29,AND(AA29>=15500,AA29<$Z$1),15500,AA29>=$Z$1,AA29*$AB$2),0) -> 18692 | AC29: =round(IF($AA29<=$Z$1,($AA29-$AB29)*AC$1,$AA29*AC$2),-1) -> 7480 | AD29: =round(IF($AA29<=$Z$1,($AA29-$AB29)*AD$1,$AA29*AD$2),-1)+AA29-AB29-AC29-round(IF($AA29<=$Z$1,($AA29-$AB29)*AD$1,$AA29*AD$2),-1) -> 11211 | AE29: 0 | AF29: =IF(SUM(AB29:AE29)=AA29,"OK","NO") -> OK | AG29: =IF(U29="US",IF(AA29<9750,"Under","US OK"),IF(U29="S",IF(AA29<12000,"Under","S OK"),"Skill Missing")) -> S OK | AH29: =VLOOKUP(A29,'Advance Sheet'!$A$4:$A$165,1,FALSE) -> #REF! | AI29: =IF(ISERROR(VLOOKUP(A29,'SNP Sal Main'!$A$3:$A1528,1,false))=FALSE,"SNP SAL",IF(ISERROR(VLOOKUP(A29,'Rest Sal Main org'!$A$3:$A1528,1,false))=FALSE,"Rest Sal","Not Found")) -> Not Found | AK29: Y | AM29: =if(J29="","",datedif(J29,$AM$2,"M")) -> 141
A30: SE1002 | B30: KHAJAN SINGH RAWAT | C30: Salary | D30: Cutting | E30: Operator | F30: SNP | G30: 0.33333333 | H30: 0.75 | I30: =IF(ISBLANK(H30),,H30-G30) -> 0.41666667 | J30: 44275 | K30: SE | L30: 28470 | M30: Chq | N30: Employed | O30: 45901 | P30: 27640 | S30: YES | T30: YES | U30: S | V30: =P30 -> 27640 | W30: 0.1 | Y30: =if(W30="",V30,round(V30*(1+W30),-1)) -> 30400 | AA30: =L30 -> 28470 | AB30: =IFS(AND(AA30<=15000),15300,AND(AA30>15000,AA30<15500),AA30,AND(AA30>=15500,AA30<$Z$1),15500,AA30>=$Z$1,AA30*$AB$2) -> 15500 | AC30: =round(IF($AA30<=$Z$1,($AA30-$AB30)*AC$1,$AA30*AC$2),-1) -> 5190 | AD30: =round(IF($AA30<=$Z$1,($AA30-$AB30)*AD$1,$AA30*AD$2),-1)+AA30-AB30-AC30-round(IF($AA30<=$Z$1,($AA30-$AB30)*AD$1,$AA30*AD$2),-1) -> 7780 | AE30: 0 | AF30: =IF(SUM(AB30:AE30)=AA30,"OK","NO") -> OK | AG30: =IF(U30="US",IF(AA30<9750,"Under","US OK"),IF(U30="S",IF(AA30<12000,"Under","S OK"),"Skill Missing")) -> S OK | AH30: =VLOOKUP(A30,'Advance Sheet'!$A$4:$A$165,1,FALSE) -> #REF! | AI30: =IF(ISERROR(VLOOKUP(A30,'SNP Sal Main'!$A$3:$A1529,1,false))=FALSE,"SNP SAL",IF(ISERROR(VLOOKUP(A30,'Rest Sal Main org'!$A$3:$A1529,1,false))=FALSE,"Rest Sal","Not Found")) -> Not Found | AK30: Y | AM30: =if(J30="","",datedif(J30,$AM$2,"M")) -> 66
A31: SE1005 | B31: DEEPAK JOSHI | C31: Salary | D31: Cutting | E31: Operator | F31: SNP | G31: 0.33333333 | H31: 0.75 | I31: =IF(ISBLANK(H31),,H31-G31) -> 0.41666667 | J31: 41974 | K31: SE | L31: 31426 | M31: Chq | N31: Employed | O31: 45901 | P31: 30510 | T31: YES | U31: S | V31: =P31 -> 30510 | W31: 0.1 | Y31: =if(W31="",V31,round(V31*(1+W31),-1)) -> 33560 | AA31: =L31 -> 31426 | AB31: =IFS(AND(AA31<=15000),15300,AND(AA31>15000,AA31<15500),AA31,AND(AA31>=15500,AA31<$Z$1),15500,AA31>=$Z$1,AA31*$AB$2) -> 15500 | AC31: =round(IF($AA31<=$Z$1,($AA31-$AB31)*AC$1,$AA31*AC$2),-1) -> 6370 | AD31: =round(IF($AA31<=$Z$1,($AA31-$AB31)*AD$1,$AA31*AD$2),-1)+AA31-AB31-AC31-round(IF($AA31<=$Z$1,($AA31-$AB31)*AD$1,$AA31*AD$2),-1) -> 9556 | AE31: 0 | AF31: =IF(SUM(AB31:AE31)=AA31,"OK","NO") -> OK | AG31: =IF(U31="US",IF(AA31<9750,"Under","US OK"),IF(U31="S",IF(AA31<12000,"Under","S OK"),"Skill Missing")) -> S OK | AH31: =VLOOKUP(A31,'Advance Sheet'!$A$4:$A$165,1,FALSE) -> #REF! | AI31: =IF(ISERROR(VLOOKUP(A31,'SNP Sal Main'!$A$3:$A1530,1,false))=FALSE,"SNP SAL",IF(ISERROR(VLOOKUP(A31,'Rest Sal Main org'!$A$3:$A1530,1,false))=FALSE,"Rest Sal","Not Found")) -> Not Found | AK31: Y | AM31: =if(J31="","",datedif(J31,$AM$2,"M")) -> 141
A32: SE1007 | B32: AMBICA YADAV | C32: Salary | D32: Cutting | E32: Helper | F32: SNP | G32: 0.33333333 | H32: 0.75 | I32: =IF(ISBLANK(H32),,H32-G32) -> 0.41666667 | J32: 41974 | K32: SE | L32: 28573 | M32: Chq | N32: Employed | O32: 45901 | P32: 27740 | S32: YES | T32: YES | U32: US | V32: =P32 -> 27740 | W32: 0.11 | Y32: =if(W32="",V32,round(V32*(1+W32),-1)) -> 30790 | AA32: =L32 -> 28573 | AB32: =IFS(AND(AA32<=15000),15300,AND(AA32>15000,AA32<15500),AA32,AND(AA32>=15500,AA32<$Z$1),15500,AA32>=$Z$1,AA32*$AB$2) -> 15500 | AC32: =round(IF($AA32<=$Z$1,($AA32-$AB32)*AC$1,$AA32*AC$2),-1) -> 5230 | AD32: =round(IF($AA32<=$Z$1,($AA32-$AB32)*AD$1,$AA32*AD$2),-1)+AA32-AB32-AC32-round(IF($AA32<=$Z$1,($AA32-$AB32)*AD$1,$AA32*AD$2),-1) -> 7843 | AE32: 0 | AF32: =IF(SUM(AB32:AE32)=AA32,"OK","NO") -> OK | AG32: =IF(U32="US",IF(AA32<9750,"Under","US OK"),IF(U32="S",IF(AA32<12000,"Under","S OK"),"Skill Missing")) -> US OK | AH32: =VLOOKUP(A32,'Advance Sheet'!$A$4:$A$165,1,FALSE) -> #REF! | AI32: =IF(ISERROR(VLOOKUP(A32,'SNP Sal Main'!$A$3:$A1531,1,false))=FALSE,"SNP SAL",IF(ISERROR(VLOOKUP(A32,'Rest Sal Main org'!$A$3:$A1531,1,false))=FALSE,"Rest Sal","Not Found")) -> Not Found | AM32: =if(J32="","",datedif(J32,$AM$2,"M")) -> 141
A33: SE1008 | B33: ERADHEY SHYAM | C33: Salary | D33: Cutting | E33: Supervisior | F33: SNP | G33: 0.33333333 | H33: 0.75 | I33: =IF(ISBLANK(H33),,H33-G33) -> 0.41666667 | J33: 41977 | K33: SE | L33: 26894 | M33: Chq | N33: Employed | O33: 45901 | P33: 26110 | S33: YES | T33: YES | U33: US | V33: =P33 -> 26110 | W33: 0.11 | Y33: =if(W33="",V33,round(V33*(1+W33),-1)) -> 28980 | AA33: =L33 -> 26894 | AB33: =IFS(AND(AA33<=15000),15300,AND(AA33>15000,AA33<15500),AA33,AND(AA33>=15500,AA33<$Z$1),15500,AA33>=$Z$1,AA33*$AB$2) -> 15500 | AC33: =round(IF($AA33<=$Z$1,($AA33-$AB33)*AC$1,$AA33*AC$2),-1) -> 4560 | AD33: =round(IF($AA33<=$Z$1,($AA33-$AB33)*AD$1,$AA33*AD$2),-1)+AA33-AB33-AC33-round(IF($AA33<=$Z$1,($AA33-$AB33)*AD$1,$AA33*AD$2),-1) -> 6834 | AE33: 0 | AF33: =IF(SUM(AB33:AE33)=AA33,"OK","NO") -> OK | AG33: =IF(U33="US",IF(AA33<9750,"Under","US OK"),IF(U33="S",IF(AA33<12000,"Under","S OK"),"Skill Missing")) -> US OK | AH33: =VLOOKUP(A33,'Advance Sheet'!$A$4:$A$165,1,FALSE) -> #REF! | AI33: =IF(ISERROR(VLOOKUP(A33,'SNP Sal Main'!$A$3:$A1532,1,false))=FALSE,"SNP SAL",IF(ISERROR(VLOOKUP(A33,'Rest Sal Main org'!$A$3:$A1532,1,false))=FALSE,"Rest Sal","Not Found")) -> Not Found | AK33: Y | AM33: =if(J33="","",datedif(J33,$AM$2,"M")) -> 141
A34: SE1009 | B34: SATYENDRA RAM | C34: Salary | D34: Cutting | E34: Supervisior | F34: SNP | G34: 0.33333333 | H34: 0.75 | I34: =IF(ISBLANK(H34),,H34-G34) -> 0.41666667 | J34: 41974 | K34: SE | L34: 31364 | M34: Chq | N34: Employed | O34: 45901 | P34: 30450 | T34: YES | U34: S | V34: =P34 -> 30450 | W34: 0.1 | Y34: =if(W34="",V34,round(V34*(1+W34),-1)) -> 33500 | AA34: =L34 -> 31364 | AB34: =IFS(AND(AA34<=15000),15300,AND(AA34>15000,AA34<15500),AA34,AND(AA34>=15500,AA34<$Z$1),15500,AA34>=$Z$1,AA34*$AB$2) -> 15500 | AC34: =round(IF($AA34<=$Z$1,($AA34-$AB34)*AC$1,$AA34*AC$2),-1) -> 6350 | AD34: =round(IF($AA34<=$Z$1,($AA34-$AB34)*AD$1,$AA34*AD$2),-1)+AA34-AB34-AC34-round(IF($AA34<=$Z$1,($AA34-$AB34)*AD$1,$AA34*AD$2),-1) -> 9514 | AE34: 0 | AF34: =IF(SUM(AB34:AE34)=AA34,"OK","NO") -> OK | AG34: =IF(U34="US",IF(AA34<9750,"Under","US OK"),IF(U34="S",IF(AA34<12000,"Under","S OK"),"Skill Missing")) -> S OK | AH34: =VLOOKUP(A34,'Advance Sheet'!$A$4:$A$165,1,FALSE) -> #REF! | AI34: =IF(ISERROR(VLOOKUP(A34,'SNP Sal Main'!$A$3:$A1533,1,false))=FALSE,"SNP SAL",IF(ISERROR(VLOOKUP(A34,'Rest Sal Main org'!$A$3:$A1533,1,false))=FALSE,"Rest Sal","Not Found")) -> Not Found | AK34: Y | AM34: =if(J34="","",datedif(J34,$AM$2,"M")) -> 141
A35: SE1012 | B35: DADAN SHARMA | C35: Salary | D35: Cutting | E35: Operator | F35: SNP | G35: 0.33333333 | H35: 0.75 | I35: =IF(ISBLANK(H35),,H35-G35) -> 0.41666667 | J35: 41978 | K35: SE | L35: 31364 | M35: Chq | N35: Employed | O35: 45901 | P35: 30450 | T35: YES | U35: S | V35: =P35 -> 30450 | W35: 0.1 | Y35: =if(W35="",V35,round(V35*(1+W35),-1)) -> 33500 | AA35: =L35 -> 31364 | AB35: =IFS(AND(AA35<=15000),15300,AND(AA35>15000,AA35<15500),AA35,AND(AA35>=15500,AA35<$Z$1),15500,AA35>=$Z$1,AA35*$AB$2) -> 15500 | AC35: =round(IF($AA35<=$Z$1,($AA35-$AB35)*AC$1,$AA35*AC$2),-1) -> 6350 | AD35: =round(IF($AA35<=$Z$1,($AA35-$AB35)*AD$1,$AA35*AD$2),-1)+AA35-AB35-AC35-round(IF($AA35<=$Z$1,($AA35-$AB35)*AD$1,$AA35*AD$2),-1) -> 9514 | AE35: 0 | AF35: =IF(SUM(AB35:AE35)=AA35,"OK","NO") -> OK | AG35: =IF(U35="US",IF(AA35<9750,"Under","US OK"),IF(U35="S",IF(AA35<12000,"Under","S OK"),"Skill Missing")) -> S OK | AH35: =VLOOKUP(A35,'Advance Sheet'!$A$4:$A$165,1,FALSE) -> #REF! | AI35: =IF(ISERROR(VLOOKUP(A35,'SNP Sal Main'!$A$3:$A1534,1,false))=FALSE,"SNP SAL",IF(ISERROR(VLOOKUP(A35,'Rest Sal Main org'!$A$3:$A1534,1,false))=FALSE,"Rest Sal","Not Found")) -> Not Found | AJ35: Y | AK35: Y | AM35: =if(J35="","",datedif(J35,$AM$2,"M")) -> 141
A36: SE1020 | B36: RAJENDRA PRASHAD JOSHI | C36: Salary | D36: Cutting | E36: Operator | F36: SNP | G36: 0.33333333 | H36: 0.75 | I36: =IF(ISBLANK(H36),,H36-G36) -> 0.41666667 | J36: 41944 | K36: SE | L36: 22134 | M36: Chq | N36: Employed | O36: 45901 | P36: 18990 | S36: YES | T36: YES | U36: S | V36: =P36 -> 18990 | W36: 0.11 | Y36: =if(W36="",V36,round(V36*(1+W36),-1)) -> 21080 | AA36: 22134 | AB36: =IFS(AND(AA36<=15000),15300,AND(AA36>15000,AA36<15500),AA36,AND(AA36>=15500,AA36<$Z$1),15500,AA36>=$Z$1,AA36*$AB$2) -> 15500 | AC36: =round(IF($AA36<=$Z$1,($AA36-$AB36)*AC$1,$AA36*AC$2),-1) -> 2650 | AD36: =round(IF($AA36<=$Z$1,($AA36-$AB36)*AD$1,$AA36*AD$2),-1)+AA36-AB36-AC36-round(IF($AA36<=$Z$1,($AA36-$AB36)*AD$1,$AA36*AD$2),-1) -> 3984 | AE36: 0 | AF36: =IF(SUM(AB36:AE36)=AA36,"OK","NO") -> OK | AG36: =IF(U36="US",IF(AA36<9750,"Under","US OK"),IF(U36="S",IF(AA36<12000,"Under","S OK"),"Skill Missing")) -> S OK | AH36: =VLOOKUP(A36,'Advance Sheet'!$A$4:$A$165,1,FALSE) -> #REF! | AI36: =IF(ISERROR(VLOOKUP(A36,'SNP Sal Main'!$A$3:$A1535,1,false))=FALSE,"SNP SAL",IF(ISERROR(VLOOKUP(A36,'Rest Sal Main org'!$A$3:$A1535,1,false))=FALSE,"Rest Sal","Not Found")) -> Not Found | AK36: Y | AM36: =if(J36="","",datedif(J36,$AM$2,"M")) -> 142
A37: SE1021 | B37: RAVI RAUSHAN KUMAR | C37: Salary | D37: Cutting | E37: Helper | F37: SNP | G37: 0.33333333 | H37: 0.75 | I37: =IF(ISBLANK(H37),,H37-G37) -> 0.41666667 | J37: 41621 | K37: SE | L37: 22470 | M37: Chq | N37: Employed | O37: 45901 | P37: 19280 | S37: YES | T37: YES | U37: US | V37: =P37 -> 19280 | W37: 0.11 | Y37: =if(W37="",V37,round(V37*(1+W37),-1)) -> 21400 | AA37: =L37 -> 22470 | AB37: =IFS(AND(AA37<=15000),15300,AND(AA37>15000,AA37<15500),AA37,AND(AA37>=15500,AA37<$Z$1),15500,AA37>=$Z$1,AA37*$AB$2) -> 15500 | AC37: =round(IF($AA37<=$Z$1,($AA37-$AB37)*AC$1,$AA37*AC$2),-1) -> 2790 | AD37: =round(IF($AA37<=$Z$1,($AA37-$AB37)*AD$1,$AA37*AD$2),-1)+AA37-AB37-AC37-round(IF($AA37<=$Z$1,($AA37-$AB37)*AD$1,$AA37*AD$2),-1) -> 4180 | AE37: 0 | AF37: =IF(SUM(AB37:AE37)=AA37,"OK","NO") -> OK | AG37: =IF(U37="US",IF(AA37<9750,"Under","US OK"),IF(U37="S",IF(AA37<12000,"Under","S OK"),"Skill Missing")) -> US OK | AH37: =VLOOKUP(A37,'Advance Sheet'!$A$4:$A$165,1,FALSE) -> #REF! | AI37: =IF(ISERROR(VLOOKUP(A37,'SNP Sal Main'!$A$3:$A1536,1,false))=FALSE,"SNP SAL",IF(ISERROR(VLOOKUP(A37,'Rest Sal Main org'!$A$3:$A1536,1,false))=FALSE,"Rest Sal","Not Found")) -> Not Found | AK37: Y | AM37: =if(J37="","",datedif(J37,$AM$2,"M")) -> 153
A38: SE1024 | B38: PRABHAT KUMAR SHRIVASTWA | C38: Salary | D38: Sales & Marketing | E38: Sales & Marketing | F38: DEL | G38: 0.41666667 | H38: 0.79166667 | I38: =IF(ISBLANK(H38),,H38-G38) -> 0.375 | J38: 41634 | K38: SE | L38: =Y38 -> 46770 | M38: Chq | N38: Employed | O38: 45901 | P38: 42910 | T38: NO | U38: S | V38: =P38 -> 42910 | W38: 0.09 | Y38: =if(W38="",V38,round(V38*(1+W38),-1)) -> 46770 | AA38: =L38 -> 46770 | AB38: =IFS(AND(AA38<=15000),15300,AND(AA38>15000,AA38<15500),AA38,AND(AA38>=15500,AA38<$Z$1),15500,AA38>=$Z$1,AA38*$AB$2) -> 23385 | AC38: =round(IF($AA38<=$Z$1,($AA38-$AB38)*AC$1,$AA38*AC$2),-1) -> 9350 | AD38: =round(IF($AA38<=$Z$1,($AA38-$AB38)*AD$1,$AA38*AD$2),-1)+AA38-AB38-AC38-round(IF($AA38<=$Z$1,($AA38-$AB38)*AD$1,$AA38*AD$2),-1) -> 14035 | AE38: 0 | AF38: =IF(SUM(AB38:AE38)=AA38,"OK","NO") -> OK | AG38: =IF(U38="US",IF(AA38<9750,"Under","US OK"),IF(U38="S",IF(AA38<12000,"Under","S OK"),"Skill Missing")) -> S OK | AH38: =VLOOKUP(A38,'Advance Sheet'!$A$4:$A$165,1,FALSE) -> #REF! | AI38: =IF(ISERROR(VLOOKUP(A38,'SNP Sal Main'!$A$3:$A1537,1,false))=FALSE,"SNP SAL",IF(ISERROR(VLOOKUP(A38,'Rest Sal Main org'!$A$3:$A1537,1,false))=FALSE,"Rest Sal","Not Found")) -> Not Found | AM38: =if(J38="","",datedif(J38,$AM$2,"M")) -> 153
A39: SE1031 | B39: JAGDISH RAI BAHL | C39: Salary | D39: Management | E39: Sales & Marketing | F39: DEL | G39: 0.375 | H39: 0.75 | I39: =IF(ISBLANK(H39),,H39-G39) -> 0.375 | J39: 42248 | K39: SE | L39: =Y39 -> 221230 | M39: Chq | N39: Employed | O39: 45901 | P39: 204840 | Q39: 39870 | T39: NO | V39: =P39 -> 204840 | W39: 0.08 | Y39: =if(W39="",V39,round(V39*(1+W39),-1)) -> 221230 | AA39: =L39 -> 221230 | AB39: =IFS(AND(AA39<=15000),15300,AND(AA39>15000,AA39<15500),AA39,AND(AA39>=15500,AA39<$Z$1),15500,AA39>=$Z$1,AA39*$AB$2) -> 110615 | AC39: =round(IF($AA39<=$Z$1,($AA39-$AB39)*AC$1,$AA39*AC$2),-1) -> 44250 | AD39: =round(IF($AA39<=$Z$1,($AA39-$AB39)*AD$1,$AA39*AD$2),-1)+AA39-AB39-AC39-round(IF($AA39<=$Z$1,($AA39-$AB39)*AD$1,$AA39*AD$2),-1) -> 66365 | AE39: 0 | AF39: =IF(SUM(AB39:AE39)=AA39,"OK","NO") -> OK | AG39: =IF(U39="US",IF(AA39<9750,"Under","US OK"),IF(U39="S",IF(AA39<12000,"Under","S OK"),"Skill Missing")) -> Skill Missing | AH39: =VLOOKUP(A39,'Advance Sheet'!$A$4:$A$165,1,FALSE) -> #REF! | AI39: =IF(ISERROR(VLOOKUP(A39,'SNP Sal Main'!$A$3:$A1538,1,false))=FALSE,"SNP SAL",IF(ISERROR(VLOOKUP(A39,'Rest Sal Main org'!$A$3:$A1538,1,false))=FALSE,"Rest Sal","Not Found")) -> Not Found | AM39: =if(J39="","",datedif(J39,$AM$2,"M")) -> 132
A40: SE1036 | B40: PRANAV JAIN | C40: Salary | D40: Office | E40: Misc | F40: DEL | G40: 0.375 | H40: 0.75 | I40: =IF(ISBLANK(H40),,H40-G40) -> 0.375 | J40: 42248 | K40: SE | L40: 80000 | M40: Chq | N40: Employed | O40: 45748 | P40: 75000 | T40: NO | V40: =P40 -> 75000 | W40: 0 | Y40: =if(W40="",V40,round(V40*(1+W40),-1)) -> 75000 | AA40: =L40 -> 80000 | AB40: 58850 | AC40: 16150 | AD40: =round(IF($AA40<=$Z$1,($AA40-$AB40)*AD$1,$AA40*AD$2),-1)+AA40-AB40-AC40-round(IF($AA40<=$Z$1,($AA40-$AB40)*AD$1,$AA40*AD$2),-1) -> 5000 | AE40: 0 | AF40: =IF(SUM(AB40:AE40)=AA40,"OK","NO") -> OK | AG40: =IF(U40="US",IF(AA40<9750,"Under","US OK"),IF(U40="S",IF(AA40<12000,"Under","S OK"),"Skill Missing")) -> Skill Missing | AH40: =VLOOKUP(A40,'Advance Sheet'!$A$4:$A$165,1,FALSE) -> #REF! | AI40: =IF(ISERROR(VLOOKUP(A40,'SNP Sal Main'!$A$3:$A1539,1,false))=FALSE,"SNP SAL",IF(ISERROR(VLOOKUP(A40,'Rest Sal Main org'!$A$3:$A1539,1,false))=FALSE,"Rest Sal","Not Found")) -> Not Found | AM40: =if(J40="","",datedif(J40,$AM$2,"M")) -> 132
...

Sheet Copy of Advance Sheet
B1: -2 | D1: =text(EOMONTH(today(),B1),"mmmyyyy")&"!A:A" -> Jul2026!A:A | E1: =text(EOMONTH(today(),B1),"mmmyyyy")&"!R:R" -> Jul2026!R:R | F1: =SUBTOTAL(9,F4:F2010) -> 82100 | G1: =SUBTOTAL(9,G4:G2010) -> 508300 | H1: =SUBTOTAL(9,H4:H2010) -> 82100 | I1: =SUBTOTAL(9,I4:I2010) -> 599200 | J1: =SUBTOTAL(9,J4:J2010) -> 98600 | K1: =SUBTOTAL(9,K4:K2010) -> 528600 | L1: =SUBTOTAL(9,L4:L2010) -> 81000 | M1: =SUBTOTAL(9,M4:M2010) -> 595600 | ... DV1: =SUBTOTAL(9,DV4:DV2010) -> 704076
F2: Deduction | G2: Outstanding | H2: Deduction | I2: Outstanding | J2: Deduction | K2: Outstanding | L2: Deduction | M2: Outstanding | N2: Deduction | O2: Outstanding | P2: Deduction | Q2: Outstanding | R2: Deduction | S2: Outstanding | T2: Deduction | U2: Outstanding | V2: Deduction | W2: Outstanding | X2: Deduction | Y2: Outstanding | Z2: Deduction | AA2: Outstanding | AB2: Deduction | AC2: Outstanding | AD2: Deduction | AE2: Outstanding | AF2: Deduction | AG2: Outstanding | AH2: Deduction | AI2: Outstanding | AJ2: Deduction | AK2: Outstanding | AL2: Deduction | AM2: Outstanding | AN2: Deduction | AO2: Outstanding | AP2: Deduction | AQ2: Outstanding | AR2: Deduction | AS2: Outstanding | AT2: Deduction | AU2: Outstanding | AV2: Deduction | AW2: Outstanding | AX2: Deduction | AY2: Outstanding | AZ2: Deduction | BA2: Outstanding | BB2: Deduction | BC2: Outstanding | BD2: Deduction | BE2: Outstanding | BF2: Deduction | BG2: Outstanding | BH2: Deduction | BI2: Outstanding | BJ2: Deduction | BK2: Outstanding | BL2: Deduction | BM2: Outstanding | BN2: Deduction | BO2: Outstanding | BP2: Deduction | BQ2: Outstanding | BR2: Deduction | BS2: Outstanding | BT2: Deduction | BU2: Outstanding | BV2: Deduction | BW2: Outstanding | BX2: Deduction | BY2: Outstanding | BZ2: Deduction | CA2: Outstanding | CB2: Deduction | CC2: Outstanding | CD2: Deduction | CE2: Outstanding | CF2: Deduction | CG2: Outstanding | CH2: Deduction | CI2: Outstanding | CJ2: Deduction | CK2: Outstanding | CL2: Deduction | CM2: Outstanding | CN2: Deduction | CO2: Outstanding | CP2: Deduction | CQ2: Outstanding | CR2: Deduction | CS2: Outstanding | CT2: Deduction | CU2: Outstanding | CV2: Deduction | CW2: Outstanding | CX2: Deduction | CY2: Deduction | CZ2: Outstanding | DA2: Deduction | DB2: Outstanding | DC2: Deduction | DD2: Outstanding | DE2: Deduction | DF2: Outstanding | DG2: Deduction | DH2: Outstanding | DI2: Deduction | DJ2: Outstanding | DK2: Deduction | DL2: Outstanding | DM2: Deduction | DN2: Outstanding | DO2: Deduction | DP2: Outstanding | DQ2: Deduction | DR2: Outstanding | DS2: Deduction | DT2: Outstanding | DU2: Deduction | DV2: Outstanding
A3: Employee Code | B3: NAME | C3: Location | D3: Department | E3: Bal Adv Today | F3: Oct2021-D | H3: 2021-D | I3: Nov2021-O | J3: Nov2021-D | K3: Dec2021-O | L3: Dec2021-D | M3: Jan2022-O | N3: Jan2022-D | O3: Feb2022-O | P3: Feb2022-D | Q3: Mar2022-O | R3: Mar2022-D | S3: Apr2022-O | T3: Apr2022-D | U3: May2022-O | V3: May2022-D | W3: Jun2022-O | X3: Jun2022-D | Y3: Jul2022-O | Z3: Jul2022-D | AA3: Aug2022-O | AB3: Aug2022-D | AC3: Sep2022-O | AD3: Sep2022-D | AE3: Oct2022-O | AF3: Oct2022-D | AG3: Nov2022-O | AH3: Nov2022-D | AI3: Dec2022-O | AJ3: Dec2022-D | AK3: Jan2023-O | AL3: Jan2023-D | AM3: Feb2023-O | AN3: Feb2023-D | AO3: Mar2023-O | AP3: Mar2023-D | AQ3: Apr2023-O | AR3: Apr2023-D | AS3: May2023-O | AT3: May2023-D | AU3: Jun2023-O | AV3: Jun2023-D | AW3: Jul2023-O | AX3: Jul2023-D | AY3: Aug2023-O | AZ3: Aug2023-D | BA3: Sep2023-O | BB3: Sep2023-D | BC3: Oct2023-O | BD3: Oct2023-D | BE3: Nov2023-O | BF3: Nov2023-D | BG3: Dec2023-O | BH3: Dec2023-D | BI3: Jan2024-O | BJ3: Jan2024-D | BK3: Feb2024-O | BL3: Feb2024-D | BM3: Mar2024-O | BN3: Mar2024-D | BO3: Apr2024-O | BP3: Apr2024-D | BQ3: May2024-O | BR3: May2024-D | BS3: Jun2024-O | BT3: Jun2024-D | BU3: Jul2024-O | BV3: Jul2024-D | BW3: Aug2024-O | BX3: Aug2024-D | BY3: Sep2024-O | BZ3: Sep2024-D | CA3: Oct2024-O | CB3: Oct2024-D | CC3: Nov2024-O | CD3: Nov2024-D | CE3: Dec2024-O | CF3: Dec2024-D | CG3: Jan2025-O | CH3: Jan2025-D | CI3: Feb2025-O | CJ3: Feb2025-D | CK3: Mar2025-O | CL3: Mar2025-D | CM3: Apr2025-O | CN3: Apr2025-D | CO3: May2025-O | CP3: May2025-D | CQ3: Jun2025-O | CR3: Jun2025-D | CS3: Jul2025-O | CT3: Jul2025-D | CU3: Aug2025-O | CV3: Aug2025-D | CW3: Sep2025-O | CX3: Sep2025-D | CY3: Bonus | CZ3: Oct2025-O | DA3: Oct2025-D | DB3: Nov2025-O | DC3: Nov2025-D | DD3: Dec2025-O | DE3: Dec2025-D | DF3: Jan2026-O | DG3: Jan2026-D | DH3: Feb2026-O | DI3: Feb2026-D | DJ3: Mar2026-O | DK3: Mar2026-D | DL3: Apr2026-O | DM3: Apr2026-D | DN3: May2026-O | DO3: May2026-D | DP3: Jun2026-O | DQ3: Jun2026-D | DR3: Jul2026-O | DS3: Jul2026-D | DT3: Aug2026-O | DU3: Aug2026-D | DV3: Sep2026-O
A4: CO1001 | B4: HARESH | C4: {=_xlfn.XLOOKUP(A4,'Emp Master'!A:A,'Emp Master'!F:F)} -> BENG | D4: {=_xlfn.XLOOKUP(A4,'Emp Master'!A:A,'Emp Master'!D:D)} -> Sales & Marketing | E4: =_xlfn.XLOOKUP(A4,INDIRECT($D$1),INDIRECT($E$1),0) -> #REF! | I4: =G4-H4 -> 0 | K4: =I4-J4 -> 0 | M4: =K4-L4 -> 0 | O4: =M4-N4 -> 0 | Q4: =O4-P4 -> 0 | S4: =Q4-R4 -> 0 | U4: =S4-T4 -> 0 | W4: =U4-V4 -> 0 | Y4: =W4-X4 -> 0 | AA4: =Y4-Z4 -> 0 | AC4: =AA4-AB4 -> 0 | AE4: =AC4-AD4 -> 0 | AG4: =AE4-AF4 -> 0 | AI4: =AG4-AH4 -> 0 | AK4: =AI4-AJ4 -> 0 | AM4: =AK4-AL4 -> 0 | AO4: =AM4-AN4 -> 0 | AQ4: =AO4-AP4 -> 0 | AS4: =AQ4-AR4 -> 0 | AU4: =AS4-AT4 -> 0 | AW4: =AU4-AV4 -> 0 | AY4: =AW4-AX4 -> 0 | BA4: =AY4-AZ4 -> 0 | BC4: =BA4-BB4 -> 0 | BE4: =BC4-BD4 -> 0 | BG4: =BE4-BF4 -> 0 | BI4: =BG4-BH4 -> 0 | BK4: =BI4-BJ4 -> 0 | BM4: =BK4-BL4 -> 0 | BO4: =BM4-BN4 -> 0 | BQ4: =BO4-BP4 -> 0 | BS4: =BQ4-BR4 -> 0 | BU4: =BS4-BT4 -> 0 | BW4: =BU4-BV4 -> 0 | BY4: =BW4-BX4 -> 0 | CA4: =BY4-BZ4 -> 0 | CC4: =CA4-CB4 -> 0 | CE4: =CC4-CD4 -> 0 | CG4: =CE4-CF4 -> 0 | CI4: =CG4-CH4 -> 0 | CK4: =CI4-CJ4 -> 0 | CM4: =CK4-CL4 -> 0 | CO4: =CM4-CN4 -> 0 | CQ4: =CO4-CP4 -> 0 | CS4: =CQ4-CR4 -> 0 | CU4: =CS4-CT4 -> 0 | CW4: =CU4-CV4 -> 0 | CZ4: =CW4-CX4 -> 0 | DB4: =CZ4-DA4 -> 0 | DD4: =DB4-DC4 -> 0 | DF4: =DD4-DE4 -> 0 | DH4: =DF4-DG4 -> 0 | DJ4: =DH4-DI4 -> 0 | DL4: =DJ4-DK4 -> 0 | DM4: 0 | DN4: =DL4-DM4 -> 0 | DO4: 0 | DP4: =DN4-DO4 -> 0 | DQ4: 0 | DR4: =DP4-DQ4 -> 0 | DS4: 0 | DT4: =DR4-DS4 -> 0 | DU4: 0 | DV4: =DT4-DU4 -> 0
A5: CO1002 | B5: V UDAI SHANKAR | C5: {=_xlfn.XLOOKUP(A5,'Emp Master'!A:A,'Emp Master'!F:F)} -> MUM | D5: {=_xlfn.XLOOKUP(A5,'Emp Master'!A:A,'Emp Master'!D:D)} -> Agent | E5: =_xlfn.XLOOKUP(A5,INDIRECT($D$1),INDIRECT($E$1),0) -> #REF! | I5: =G5-H5 -> 0 | K5: =I5-J5 -> 0 | M5: =K5-L5 -> 0 | O5: =M5-N5 -> 0 | Q5: =O5-P5 -> 0 | S5: =Q5-R5 -> 0 | U5: =S5-T5 -> 0 | W5: =U5-V5 -> 0 | Y5: =W5-X5 -> 0 | AA5: =Y5-Z5 -> 0 | AC5: =AA5-AB5 -> 0 | AE5: =AC5-AD5 -> 0 | AG5: =AE5-AF5 -> 0 | AI5: =AG5-AH5 -> 0 | AK5: =AI5-AJ5 -> 0 | AM5: =AK5-AL5 -> 0 | AO5: =AM5-AN5 -> 0 | AQ5: =AO5-AP5 -> 0 | AS5: =AQ5-AR5 -> 0 | AU5: =AS5-AT5 -> 0 | AW5: =AU5-AV5 -> 0 | AY5: =AW5-AX5 -> 0 | BA5: =AY5-AZ5 -> 0 | BC5: =BA5-BB5 -> 0 | BE5: =BC5-BD5 -> 0 | BG5: =BE5-BF5 -> 0 | BI5: =BG5-BH5 -> 0 | BK5: =BI5-BJ5 -> 0 | BM5: =BK5-BL5 -> 0 | BO5: =BM5-BN5 -> 0 | BQ5: =BO5-BP5 -> 0 | BS5: =BQ5-BR5 -> 0 | BU5: =BS5-BT5 -> 0 | BW5: =BU5-BV5 -> 0 | BY5: =BW5-BX5 -> 0 | CA5: =BY5-BZ5 -> 0 | CC5: =CA5-CB5 -> 0 | CE5: =CC5-CD5 -> 0 | CG5: =CE5-CF5 -> 0 | CI5: =CG5-CH5 -> 0 | CK5: =CI5-CJ5 -> 0 | CM5: =CK5-CL5 -> 0 | CO5: =CM5-CN5 -> 0 | CQ5: =CO5-CP5 -> 0 | CS5: =CQ5-CR5 -> 0 | CU5: =CS5-CT5 -> 0 | CW5: =CU5-CV5 -> 0 | CZ5: =CW5-CX5 -> 0 | DB5: =CZ5-DA5 -> 0 | DD5: =DB5-DC5 -> 0 | DF5: =DD5-DE5 -> 0 | DH5: =DF5-DG5 -> 0 | DJ5: =DH5-DI5 -> 0 | DL5: =DJ5-DK5 -> 0 | DM5: 0 | DN5: =DL5-DM5 -> 0 | DO5: 0 | DP5: =DN5-DO5 -> 0 | DQ5: 0 | DR5: =DP5-DQ5 -> 0 | DS5: 0 | DT5: =DR5-DS5 -> 0 | DU5: 0 | DV5: =DT5-DU5 -> 0
A6: CO1003 | B6: VARUN KAUSHAL | C6: {=_xlfn.XLOOKUP(A6,'Emp Master'!A:A,'Emp Master'!F:F)} -> DEL | D6: {=_xlfn.XLOOKUP(A6,'Emp Master'!A:A,'Emp Master'!D:D)} -> Sales & Marketing | E6: =_xlfn.XLOOKUP(A6,INDIRECT($D$1),INDIRECT($E$1),0) -> #REF! | I6: 0 | K6: =I6-J6 -> 0 | M6: =K6-L6 -> 0 | O6: =M6-N6 -> 0 | Q6: =O6-P6 -> 0 | S6: =Q6-R6 -> 0 | U6: =S6-T6 -> 0 | W6: =U6-V6 -> 0 | Y6: =W6-X6 -> 0 | AA6: =Y6-Z6 -> 0 | AC6: =AA6-AB6 -> 0 | AE6: =AC6-AD6 -> 0 | AG6: =AE6-AF6 -> 0 | AI6: =AG6-AH6 -> 0 | AK6: =AI6-AJ6 -> 0 | AM6: =AK6-AL6 -> 0 | AO6: =AM6-AN6 -> 0 | AQ6: =AO6-AP6 -> 0 | AS6: =AQ6-AR6 -> 0 | AU6: =AS6-AT6 -> 0 | AW6: =AU6-AV6 -> 0 | AY6: =AW6-AX6 -> 0 | BA6: =AY6-AZ6 -> 0 | BC6: =BA6-BB6 -> 0 | BE6: =BC6-BD6 -> 0 | BG6: =BE6-BF6 -> 0 | BI6: =BG6-BH6 -> 0 | BK6: =BI6-BJ6 -> 0 | BM6: =BK6-BL6 -> 0 | BO6: =BM6-BN6 -> 0 | BQ6: =BO6-BP6 -> 0 | BS6: =BQ6-BR6 -> 0 | BU6: =BS6-BT6 -> 0 | BW6: =BU6-BV6 -> 0 | BY6: =BW6-BX6 -> 0 | CA6: =BY6-BZ6 -> 0 | CC6: =CA6-CB6 -> 0 | CE6: =CC6-CD6 -> 0 | CG6: =CE6-CF6 -> 0 | CI6: =CG6-CH6 -> 0 | CK6: =CI6-CJ6 -> 0 | CM6: =CK6-CL6 -> 0 | CO6: =CM6-CN6 -> 0 | CQ6: =CO6-CP6 -> 0 | CS6: =CQ6-CR6 -> 0 | CU6: =CS6-CT6 -> 0 | CW6: =CU6-CV6 -> 0 | CZ6: =CW6-CX6 -> 0 | DB6: =CZ6-DA6 -> 0 | DD6: =DB6-DC6 -> 0 | DF6: =DD6-DE6 -> 0 | DH6: =DF6-DG6 -> 0 | DJ6: =DH6-DI6 -> 0 | DL6: =DJ6-DK6 -> 0 | DM6: 0 | DN6: =DL6-DM6 -> 0 | DO6: 0 | DP6: =DN6-DO6 -> 0 | DQ6: 0 | DR6: =DP6-DQ6 -> 0 | DS6: 0 | DT6: =DR6-DS6 -> 0 | DU6: 0 | DV6: =DT6-DU6 -> 0
A7: CS1003 | B7: BABLI | C7: {=_xlfn.XLOOKUP(A7,'Emp Master'!A:A,'Emp Master'!F:F)} -> #N/A | D7: {=_xlfn.XLOOKUP(A7,'Emp Master'!A:A,'Emp Master'!D:D)} -> #N/A | E7: =_xlfn.XLOOKUP(A7,INDIRECT($D$1),INDIRECT($E$1),0) -> #REF! | I7: =G7-H7 -> 0 | K7: =I7-J7 -> 0 | M7: =K7-L7 -> 0 | O7: =M7-N7 -> 0 | Q7: =O7-P7 -> 0 | S7: =Q7-R7 -> 0 | U7: =S7-T7 -> 0 | W7: =U7-V7 -> 0 | Y7: =W7-X7 -> 0 | AA7: =Y7-Z7 -> 0 | AC7: =AA7-AB7 -> 0 | AE7: =AC7-AD7 -> 0 | AG7: =AE7-AF7 -> 0 | AI7: =AG7-AH7 -> 0 | AK7: =AI7-AJ7 -> 0 | AM7: =AK7-AL7 -> 0 | AO7: =AM7-AN7 -> 0 | AQ7: =AO7-AP7 -> 0 | AS7: =AQ7-AR7 -> 0 | AU7: =AS7-AT7 -> 0 | AW7: =AU7-AV7 -> 0 | AY7: =AW7-AX7 -> 0 | BA7: =AY7-AZ7 -> 0 | BC7: =BA7-BB7 -> 0 | BE7: =BC7-BD7 -> 0 | BG7: =BE7-BF7 -> 0 | BI7: =BG7-BH7 -> 0 | BK7: =BI7-BJ7 -> 0 | BM7: =BK7-BL7 -> 0 | BO7: =BM7-BN7 -> 0 | BQ7: =BO7-BP7 -> 0 | BS7: =BQ7-BR7 -> 0 | BU7: =BS7-BT7 -> 0 | BW7: =BU7-BV7 -> 0 | BY7: =BW7-BX7 -> 0 | CA7: =BY7-BZ7 -> 0 | CC7: =CA7-CB7 -> 0 | CE7: =CC7-CD7 -> 0 | CG7: =CE7-CF7 -> 0 | CI7: =CG7-CH7 -> 0 | CK7: =CI7-CJ7 -> 0 | CM7: =CK7-CL7 -> 0 | CO7: =CM7-CN7 -> 0 | CQ7: =CO7-CP7 -> 0 | CS7: =CQ7-CR7 -> 0 | CU7: =CS7-CT7 -> 0 | CW7: =CU7-CV7 -> 0 | CZ7: =CW7-CX7 -> 0 | DB7: =CZ7-DA7 -> 0 | DD7: =DB7-DC7 -> 0 | DF7: =DD7-DE7 -> 0 | DH7: =DF7-DG7 -> 0 | DJ7: =DH7-DI7 -> 0 | DL7: =DJ7-DK7 -> 0 | DM7: 0 | DN7: =DL7-DM7 -> 0 | DO7: 0 | DP7: =DN7-DO7 -> 0 | DQ7: 0 | DR7: =DP7-DQ7 -> 0 | DS7: 0 | DT7: =DR7-DS7 -> 0 | DU7: 0 | DV7: =DT7-DU7 -> 0
A8: CS1004 | B8: CHINKI | C8: {=_xlfn.XLOOKUP(A8,'Emp Master'!A:A,'Emp Master'!F:F)} -> #N/A | D8: {=_xlfn.XLOOKUP(A8,'Emp Master'!A:A,'Emp Master'!D:D)} -> #N/A | E8: =_xlfn.XLOOKUP(A8,INDIRECT($D$1),INDIRECT($E$1),0) -> #REF! | I8: =G8-H8 -> 0 | K8: =I8-J8 -> 0 | M8: =K8-L8 -> 0 | O8: =M8-N8 -> 0 | Q8: =O8-P8 -> 0 | S8: =Q8-R8 -> 0 | U8: =S8-T8 -> 0 | W8: =U8-V8 -> 0 | Y8: =W8-X8 -> 0 | AA8: =Y8-Z8 -> 0 | AC8: =AA8-AB8 -> 0 | AE8: =AC8-AD8 -> 0 | AG8: =AE8-AF8 -> 0 | AI8: =AG8-AH8 -> 0 | AK8: =AI8-AJ8 -> 0 | AM8: =AK8-AL8 -> 0 | AO8: =AM8-AN8 -> 0 | AQ8: =AO8-AP8 -> 0 | AS8: =AQ8-AR8 -> 0 | AU8: =AS8-AT8 -> 0 | AW8: =AU8-AV8 -> 0 | AY8: =AW8-AX8 -> 0 | BA8: =AY8-AZ8 -> 0 | BC8: =BA8-BB8 -> 0 | BE8: =BC8-BD8 -> 0 | BG8: =BE8-BF8 -> 0 | BI8: =BG8-BH8 -> 0 | BK8: =BI8-BJ8 -> 0 | BM8: =BK8-BL8 -> 0 | BO8: =BM8-BN8 -> 0 | BQ8: =BO8-BP8 -> 0 | BS8: =BQ8-BR8 -> 0 | BU8: =BS8-BT8 -> 0 | BW8: =BU8-BV8 -> 0 | BY8: =BW8-BX8 -> 0 | CA8: =BY8-BZ8 -> 0 | CC8: =CA8-CB8 -> 0 | CE8: =CC8-CD8 -> 0 | CG8: =CE8-CF8 -> 0 | CI8: =CG8-CH8 -> 0 | CK8: =CI8-CJ8 -> 0 | CM8: =CK8-CL8 -> 0 | CO8: =CM8-CN8 -> 0 | CQ8: =CO8-CP8 -> 0 | CS8: =CQ8-CR8 -> 0 | CU8: =CS8-CT8 -> 0 | CW8: =CU8-CV8 -> 0 | CZ8: =CW8-CX8 -> 0 | DB8: =CZ8-DA8 -> 0 | DD8: =DB8-DC8 -> 0 | DF8: =DD8-DE8 -> 0 | DH8: =DF8-DG8 -> 0 | DJ8: =DH8-DI8 -> 0 | DL8: =DJ8-DK8 -> 0 | DM8: 0 | DN8: =DL8-DM8 -> 0 | DO8: 0 | DP8: =DN8-DO8 -> 0 | DQ8: 0 | DR8: =DP8-DQ8 -> 0 | DS8: 0 | DT8: =DR8-DS8 -> 0 | DU8: 0 | DV8: =DT8-DU8 -> 0
A9: CS1010 | B9: Vinod | C9: {=_xlfn.XLOOKUP(A9,'Emp Master'!A:A,'Emp Master'!F:F)} -> #N/A | D9: {=_xlfn.XLOOKUP(A9,'Emp Master'!A:A,'Emp Master'!D:D)} -> #N/A | E9: =_xlfn.XLOOKUP(A9,INDIRECT($D$1),INDIRECT($E$1),0) -> #REF! | I9: =G9-H9 -> 0 | K9: =I9-J9 -> 0 | M9: =K9-L9 -> 0 | O9: =M9-N9 -> 0 | Q9: =O9-P9 -> 0 | S9: =Q9-R9 -> 0 | U9: =S9-T9 -> 0 | W9: =U9-V9 -> 0 | Y9: =W9-X9 -> 0 | AA9: =Y9-Z9 -> 0 | AC9: =AA9-AB9 -> 0 | AE9: =AC9-AD9 -> 0 | AG9: =AE9-AF9 -> 0 | AI9: =AG9-AH9 -> 0 | AK9: =AI9-AJ9 -> 0 | AM9: =AK9-AL9 -> 0 | AO9: =AM9-AN9 -> 0 | AQ9: =AO9-AP9 -> 0 | AS9: =AQ9-AR9 -> 0 | AU9: =AS9-AT9 -> 0 | AW9: =AU9-AV9 -> 0 | AY9: =AW9-AX9 -> 0 | BA9: =AY9-AZ9 -> 0 | BC9: =BA9-BB9 -> 0 | BE9: =BC9-BD9 -> 0 | BG9: =BE9-BF9 -> 0 | BI9: =BG9-BH9 -> 0 | BK9: =BI9-BJ9 -> 0 | BM9: =BK9-BL9 -> 0 | BO9: =BM9-BN9 -> 0 | BQ9: =BO9-BP9 -> 0 | BS9: =BQ9-BR9 -> 0 | BU9: =BS9-BT9 -> 0 | BW9: =BU9-BV9 -> 0 | BY9: =BW9-BX9 -> 0 | CA9: =BY9-BZ9 -> 0 | CC9: =CA9-CB9 -> 0 | CE9: =CC9-CD9 -> 0 | CG9: =CE9-CF9 -> 0 | CI9: =CG9-CH9 -> 0 | CK9: =CI9-CJ9 -> 0 | CM9: =CK9-CL9 -> 0 | CO9: =CM9-CN9 -> 0 | CQ9: =CO9-CP9 -> 0 | CS9: =CQ9-CR9 -> 0 | CU9: =CS9-CT9 -> 0 | CW9: =CU9-CV9 -> 0 | CZ9: =CW9-CX9 -> 0 | DB9: =CZ9-DA9 -> 0 | DD9: =DB9-DC9 -> 0 | DF9: =DD9-DE9 -> 0 | DH9: =DF9-DG9 -> 0 | DJ9: =DH9-DI9 -> 0 | DL9: =DJ9-DK9 -> 0 | DM9: 0 | DN9: =DL9-DM9 -> 0 | DO9: 0 | DP9: =DN9-DO9 -> 0 | DQ9: 0 | DR9: =DP9-DQ9 -> 0 | DS9: 0 | DT9: =DR9-DS9 -> 0 | DU9: 0 | DV9: =DT9-DU9 -> 0
A10: CS1011 | B10: JAIDEEP | C10: {=_xlfn.XLOOKUP(A10,'Emp Master'!A:A,'Emp Master'!F:F)} -> #N/A | D10: {=_xlfn.XLOOKUP(A10,'Emp Master'!A:A,'Emp Master'!D:D)} -> #N/A | E10: =_xlfn.XLOOKUP(A10,INDIRECT($D$1),INDIRECT($E$1),0) -> #REF! | I10: =G10-H10 -> 0 | K10: =I10-J10 -> 0 | M10: =K10-L10 -> 0 | O10: =M10-N10 -> 0 | Q10: =O10-P10 -> 0 | S10: =Q10-R10 -> 0 | U10: =S10-T10 -> 0 | W10: =U10-V10 -> 0 | Y10: =W10-X10 -> 0 | AA10: =Y10-Z10 -> 0 | AC10: =AA10-AB10 -> 0 | AE10: =AC10-AD10 -> 0 | AG10: =AE10-AF10 -> 0 | AI10: =AG10-AH10 -> 0 | AK10: =AI10-AJ10 -> 0 | AM10: =AK10-AL10 -> 0 | AO10: =AM10-AN10 -> 0 | AQ10: =AO10-AP10 -> 0 | AS10: =AQ10-AR10 -> 0 | AU10: =AS10-AT10 -> 0 | AW10: =AU10-AV10 -> 0 | AY10: =AW10-AX10 -> 0 | BA10: =AY10-AZ10 -> 0 | BC10: =BA10-BB10 -> 0 | BE10: =BC10-BD10 -> 0 | BG10: =BE10-BF10 -> 0 | BI10: =BG10-BH10 -> 0 | BK10: =BI10-BJ10 -> 0 | BM10: =BK10-BL10 -> 0 | BO10: =BM10-BN10 -> 0 | BQ10: =BO10-BP10 -> 0 | BS10: =BQ10-BR10 -> 0 | BU10: =BS10-BT10 -> 0 | BW10: =BU10-BV10 -> 0 | BY10: =BW10-BX10 -> 0 | CA10: =BY10-BZ10 -> 0 | CC10: =CA10-CB10 -> 0 | CE10: =CC10-CD10 -> 0 | CG10: =CE10-CF10 -> 0 | CI10: =CG10-CH10 -> 0 | CK10: =CI10-CJ10 -> 0 | CM10: =CK10-CL10 -> 0 | CO10: =CM10-CN10 -> 0 | CQ10: =CO10-CP10 -> 0 | CS10: =CQ10-CR10 -> 0 | CU10: =CS10-CT10 -> 0 | CW10: =CU10-CV10 -> 0 | CZ10: =CW10-CX10 -> 0 | DB10: =CZ10-DA10 -> 0 | DD10: =DB10-DC10 -> 0 | DF10: =DD10-DE10 -> 0 | DH10: =DF10-DG10 -> 0 | DJ10: =DH10-DI10 -> 0 | DL10: =DJ10-DK10 -> 0 | DM10: 0 | DN10: =DL10-DM10 -> 0 | DO10: 0 | DP10: =DN10-DO10 -> 0 | DQ10: 0 | DR10: =DP10-DQ10 -> 0 | DS10: 0 | DT10: =DR10-DS10 -> 0 | DU10: 0 | DV10: =DT10-DU10 -> 0
